Workbook
Name 간호과근로계약서: #REF!
Name 간호과근로계약서: #REF!
Name 간호과근로계약서: #REF!
Name 간호과근로계약서: #REF!
Name 간호과근로계약서: #REF!
Name 간호과근로계약서: #REF!
Name 디비: #REF!
Name 디비: #REF!
Name 디비: #REF!
Name 디비: #REF!
Name 디비: #REF!
Name 디비: #REF!
Name 디비: #REF!
Name 디비: #REF!
Name 디비: #REF!
Name ㅁㄴ: #REF!
Name ㅁㄴ: #REF!
Name ㅁㄴ: #REF!
Name ㅁㄴ: #REF!
Name ㅁㄴ: #REF!
Name ㅁㄴ: #REF!
Name 보험료공제: #REF!
Name 보험료공제: #REF!
Name 보험료공제: #REF!
Name 보험료공제: #REF!
Name 보험료공제: #REF!
Name 보험료공제: #REF!
Name 보험료공제: #REF!
Name 보험료공제: #REF!
Name 보험료공제: #REF!
Name 보험료공제1: #REF!
Name 보험료공제1: #REF!
Name 보험료공제1: #REF!
Name 보험료공제1: #REF!
Name 보험료공제1: #REF!
Name 보험료공제1: #REF!
Name 보험료공제1: #REF!
Name 보험료공제1: #REF!
Name 보험료공제1: #REF!
Name ㅇㄴㅁ: #REF!
Name ㅇㄴㅁ: #REF!
Name ㅇㄴㅁ: #REF!
Name ㅇㄴㅁ: #REF!
Name ㅇㄴㅁ: #REF!
Name ㅇㄴㅁ: #REF!
Name 직능2: #REF!
Name 직능2: #REF!
Name 직능2: #REF!
Name 직능2: #REF!
Name 직능2: #REF!
Name 직능2: #REF!
Name 직능2: #REF!
Name 직능2: #REF!
Name 직능2: #REF!
Name 직능3: #REF!
Name 직능3: #REF!
Name 직능3: #REF!
Name 직능3: #REF!
Name 직능3: #REF!
Name 직능3: #REF!

Sheet 세액표(1202)
B1: 1 | C1: 2 | D1: 3 | E1: 4 | F1: 5 | G1: 6 | H1: 7 | I1: 8 | J1: 9 | K1: 10 | L1: 11
A2: 775000 | B2: 0 | C2: 0 | D2: 0 | E2: 0 | F2: 0 | G2: 0 | H2: 0 | I2: 0 | J2: 0 | K2: 0 | L2: 0 | M2: 0 | N2: 0 | O2: 0 | P2: 0 | Q2: 0 | R2: 0 | S2: 0 | T2: 0 | U2: 0
A3: 780000 | B3: 0 | C3: 0 | D3: 0 | E3: 0 | F3: 0 | G3: 0 | H3: 0 | I3: 0 | J3: 0 | K3: 0 | L3: 0 | M3: 0 | N3: 0 | O3: 0 | P3: 0 | Q3: 0 | R3: 0 | S3: 0 | T3: 0 | U3: 0
A4: 785000 | B4: 0 | C4: 0 | D4: 0 | E4: 0 | F4: 0 | G4: 0 | H4: 0 | I4: 0 | J4: 0 | K4: 0 | L4: 0 | M4: 0 | N4: 0 | O4: 0 | P4: 0 | Q4: 0 | R4: 0 | S4: 0 | T4: 0 | U4: 0
A5: 790000 | B5: 0 | C5: 0 | D5: 0 | E5: 0 | F5: 0 | G5: 0 | H5: 0 | I5: 0 | J5: 0 | K5: 0 | L5: 0 | M5: 0 | N5: 0 | O5: 0 | P5: 0 | Q5: 0 | R5: 0 | S5: 0 | T5: 0 | U5: 0
A6: 795000 | B6: 0 | C6: 0 | D6: 0 | E6: 0 | F6: 0 | G6: 0 | H6: 0 | I6: 0 | J6: 0 | K6: 0 | L6: 0 | M6: 0 | N6: 0 | O6: 0 | P6: 0 | Q6: 0 | R6: 0 | S6: 0 | T6: 0 | U6: 0
A7: 800000 | B7: 0 | C7: 0 | D7: 0 | E7: 0 | F7: 0 | G7: 0 | H7: 0 | I7: 0 | J7: 0 | K7: 0 | L7: 0 | M7: 0 | N7: 0 | O7: 0 | P7: 0 | Q7: 0 | R7: 0 | S7: 0 | T7: 0 | U7: 0
A8: 805000 | B8: 0 | C8: 0 | D8: 0 | E8: 0 | F8: 0 | G8: 0 | H8: 0 | I8: 0 | J8: 0 | K8: 0 | L8: 0 | M8: 0 | N8: 0 | O8: 0 | P8: 0 | Q8: 0 | R8: 0 | S8: 0 | T8: 0 | U8: 0
A9: 810000 | B9: 0 | C9: 0 | D9: 0 | E9: 0 | F9: 0 | G9: 0 | H9: 0 | I9: 0 | J9: 0 | K9: 0 | L9: 0 | M9: 0 | N9: 0 | O9: 0 | P9: 0 | Q9: 0 | R9: 0 | S9: 0 | T9: 0 | U9: 0
A10: 815000 | B10: 0 | C10: 0 | D10: 0 | E10: 0 | F10: 0 | G10: 0 | H10: 0 | I10: 0 | J10: 0 | K10: 0 | L10: 0 | M10: 0 | N10: 0 | O10: 0 | P10: 0 | Q10: 0 | R10: 0 | S10: 0 | T10: 0 | U10: 0
A11: 820000 | B11: 0 | C11: 0 | D11: 0 | E11: 0 | F11: 0 | G11: 0 | H11: 0 | I11: 0 | J11: 0 | K11: 0 | L11: 0 | M11: 0 | N11: 0 | O11: 0 | P11: 0 | Q11: 0 | R11: 0 | S11: 0 | T11: 0 | U11: 0
A12: 825000 | B12: 0 | C12: 0 | D12: 0 | E12: 0 | F12: 0 | G12: 0 | H12: 0 | I12: 0 | J12: 0 | K12: 0 | L12: 0 | M12: 0 | N12: 0 | O12: 0 | P12: 0 | Q12: 0 | R12: 0 | S12: 0 | T12: 0 | U12: 0
A13: 830000 | B13: 0 | C13: 0 | D13: 0 | E13: 0 | F13: 0 | G13: 0 | H13: 0 | I13: 0 | J13: 0 | K13: 0 | L13: 0 | M13: 0 | N13: 0 | O13: 0 | P13: 0 | Q13: 0 | R13: 0 | S13: 0 | T13: 0 | U13: 0
... A58: 1055000 | B58: 0 | C58: 0 | D58: 0 | E58: 0 | F58: 0 | G58: 0 | H58: 0 | I58: 0 | J58: 0 | K58: 0 | L58: 0 | M58: 0 | N58: 0 | O58: 0 | P58: 0 | Q58: 0 | R58: 0 | S58: 0 | T58: 0 | U58: 0
A59: 1060000 | B59: 0 | C59: 0 | D59: 0 | E59: 0 | F59: 0 | G59: 0 | H59: 0 | I59: 0 | M59: 0 | N59: 0 | O59: 0 | P59: 0 | Q59: 0 | R59: 0 | S59: 0 | T59: 0 | U59: 0
A60: 1065000 | B60: 1040 | C60: 0 | D60: 0 | E60: 0 | F60: 0 | G60: 0 | H60: 0 | I60: 0 | M60: 0 | N60: 0 | O60: 0 | P60: 0 | Q60: 0 | R60: 0 | S60: 0 | T60: 0 | U60: 0
A61: 1070000 | B61: 1110 | C61: 0 | D61: 0 | E61: 0 | F61: 0 | G61: 0 | H61: 0 | I61: 0 | M61: 0 | N61: 0 | O61: 0 | P61: 0 | Q61: 0 | R61: 0 | S61: 0 | T61: 0 | U61: 0
A62: 1075000 | B62: 1180 | C62: 0 | D62: 0 | E62: 0 | F62: 0 | G62: 0 | H62: 0 | I62: 0 | M62: 0 | N62: 0 | O62: 0 | P62: 0 | Q62: 0 | R62: 0 | S62: 0 | T62: 0 | U62: 0
A63: 1080000 | B63: 1250 | C63: 0 | D63: 0 | E63: 0 | F63: 0 | G63: 0 | H63: 0 | I63: 0 | M63: 0 | N63: 0 | O63: 0 | P63: 0 | Q63: 0 | R63: 0 | S63: 0 | T63: 0 | U63: 0
A64: 1085000 | B64: 1320 | C64: 0 | D64: 0 | E64: 0 | F64: 0 | G64: 0 | H64: 0 | I64: 0 | M64: 0 | N64: 0 | O64: 0 | P64: 0 | Q64: 0 | R64: 0 | S64: 0 | T64: 0 | U64: 0
A65: 1090000 | B65: 1390 | C65: 0 | D65: 0 | E65: 0 | F65: 0 | G65: 0 | H65: 0 | I65: 0 | M65: 0 | N65: 0 | O65: 0 | P65: 0 | Q65: 0 | R65: 0 | S65: 0 | T65: 0 | U65: 0
A66: 1095000 | B66: 1460 | C66: 0 | D66: 0 | E66: 0 | F66: 0 | G66: 0 | H66: 0 | I66: 0 | M66: 0 | N66: 0 | O66: 0 | P66: 0 | Q66: 0 | R66: 0 | S66: 0 | T66: 0 | U66: 0
A67: 1100000 | B67: 1530 | C67: 0 | D67: 0 | E67: 0 | F67: 0 | G67: 0 | H67: 0 | I67: 0 | M67: 0 | N67: 0 | O67: 0 | P67: 0 | Q67: 0 | R67: 0 | S67: 0 | T67: 0 | U67: 0
A68: 1105000 | B68: 1600 | C68: 0 | D68: 0 | E68: 0 | F68: 0 | G68: 0 | H68: 0 | I68: 0 | M68: 0 | N68: 0 | O68: 0 | P68: 0 | Q68: 0 | R68: 0 | S68: 0 | T68: 0 | U68: 0
A69: 1110000 | B69: 1670 | C69: 0 | D69: 0 | E69: 0 | F69: 0 | G69: 0 | H69: 0 | I69: 0 | M69: 0 | N69: 0 | O69: 0 | P69: 0 | Q69: 0 | R69: 0 | S69: 0 | T69: 0 | U69: 0
A70: 1115000 | B70: 1740 | C70: 0 | D70: 0 | E70: 0 | F70: 0 | G70: 0 | H70: 0 | I70: 0 | M70: 0 | N70: 0 | O70: 0 | P70: 0 | Q70: 0 | R70: 0 | S70: 0 | T70: 0 | U70: 0
... A225: 2280000 | B225: 28200 | C225: 21200 | D225: 11960 | E225: 8580 | F225: 5210 | G225: 1830 | H225: 0 | I225: 0 | M225: 0 | N225: 0 | O225: 0 | P225: 0 | Q225: 0 | R225: 0 | S225: 0 | T225: 0 | U225: 0
A226: 2290000 | B226: 28520 | C226: 21520 | D226: 12150 | E226: 8780 | F226: 5400 | G226: 2030 | H226: 0 | I226: 0
A227: 2300000 | B227: 28840 | C227: 21840 | D227: 12350 | E227: 8980 | F227: 5600 | G227: 2230 | H227: 0 | I227: 0
A228: 2310000 | B228: 29160 | C228: 22160 | D228: 12550 | E228: 9180 | F228: 5800 | G228: 2430 | H228: 0 | I228: 0
A229: 2320000 | B229: 29480 | C229: 22480 | D229: 12750 | E229: 9370 | F229: 6000 | G229: 2620 | H229: 0 | I229: 0
A230: 2330000 | B230: 29810 | C230: 22810 | D230: 12950 | E230: 9570 | F230: 6200 | G230: 2820 | H230: 0 | I230: 0
A231: 2340000 | B231: 30130 | C231: 23130 | D231: 13150 | E231: 9770 | F231: 6400 | G231: 3020 | H231: 0 | I231: 0
A232: 2350000 | B232: 30450 | C232: 23450 | D232: 13340 | E232: 9970 | F232: 6590 | G232: 3220 | H232: 0 | I232: 0
A233: 2360000 | B233: 30770 | C233: 23770 | D233: 13540 | E233: 10170 | F233: 6790 | G233: 3420 | H233: 0 | I233: 0
A234: 2370000 | B234: 31090 | C234: 24090 | D234: 13740 | E234: 10370 | F234: 6990 | G234: 3620 | H234: 0 | I234: 0
A235: 2380000 | B235: 31410 | C235: 24410 | D235: 13940 | E235: 10560 | F235: 7190 | G235: 3810 | H235: 0 | I235: 0
A236: 2390000 | B236: 31730 | C236: 24730 | D236: 14140 | E236: 10760 | F236: 7390 | G236: 4010 | H236: 0 | I236: 0
A237: 2400000 | B237: 32050 | C237: 25050 | D237: 14340 | E237: 10960 | F237: 7590 | G237: 4210 | H237: 0 | I237: 0
... A269: 2720000 | B269: 49100 | C269: 35790 | D269: 22220 | E269: 17600 | F269: 14230 | G269: 10850 | H269: 7480 | I269: 4100
...

Sheet 임금대장
A1: 2026년 1월 지급내역 | W1: 2026년 1월 공제내역
A3: <쿠우쿠우 부평점> | M3: =VALUE(LEFT(A1,4)) -> 2026 | N3: =VALUE(MID(A1,FIND("년",A1)+2,FIND("월",A1)-FIND("년",A1)-2)) -> 1 | O3: =DAY(EOMONTH(DATE(VALUE(LEFT(A1,4)), N3, 1), 0)) -> 31 | W3: <쿠우쿠우 부평점>
A4: 번호 | B4: 이름 | C4: 파트 | D4: 주민등록번호 | E4: 입사일 | F4: 퇴사일 | G4: 계약임금 | H4: 시급 | I4: 지 급 내 역 | O4: 근무일 | P4: 휴무 | Q4: 휴무공제 | R4: 차감시간 | S4: 시간공제 | T4: 임금총액 | W4: 번호 | X4: 이름 | Y4: 공 제 내 역 | AG4: 공제액계 | AH4: 실지급액 | AI4: 비고
I5: 기본급 | J5: 연장근로 (고정) | K5: 고정추가수당 | L5: 휴일근무+ 추가수당 | M5: 연차수당 | N5: 추가수당 | U5: 소득금액 | V5: 가족수 | Y5: 소득세 | Z5: 주민세 | AA5: 국민연금 | AB5: 건강보험 | AC5: 장기요양보험 | AD5: 고용보험료 | AE5: 기지급액 | AF5: 퇴직정산 | AL5: 12 | AM5: 11 | AN5: 10 | AO5: 9 | AP5: 8 | AQ5: 7 | AR5: 6 | AS5: 5 | AT5: 4 | AU5: 3 | AV5: 2 | AW5: 1
A6: =ROW()-5 -> 1 | B6: 박은규 | C6: =INDEX('정직원 (2)'!$B$4:$B$10,MATCH(임금대장!B6,'정직원 (2)'!$C$4:$C$10,0)) -> 초다이 | D6: =VLOOKUP(B6,'정직원 (2)'!$C$4:$F$10,4,0) -> 870923-1243215 | E6: =VLOOKUP(B6,'정직원 (2)'!$C$4:$J$81,8,0) -> 44593 | F6: =VLOOKUP(B6,'정직원 (2)'!$C$4:$L$81,10,0) -> 0 | G6: =VLOOKUP(B6,'정직원 (2)'!$C$4:$F$81,3,0) -> 4300000 | H6: =ROUNDDOWN(G6/291,0) -> 14776 | I6: =ROUNDDOWN(($G6/291*209),0) -> 3088316 | J6: =ROUNDDOWN(($G6/291*65.2),0) -> 963436 | K6: =ROUNDUP(($G6/291*8.8),0) -> 130035 | L6: =VLOOKUP(B6,'정직원 (2)'!$C$4:$O$95,13,0) -> 0 | M6: =ROUNDDOWN(($G6/291*8),0) -> 118213 | N6: =IF(OR(AI6="",AI6=0),0, IF(ISNUMBER(SEARCH("추가",AI6)), G6/$O$3*VALUE(SUBSTITUTE(SUBSTITUTE(TRIM(AI6)," ",""),"추가","")), 0)) -> 69354.839 | O6: =$O$3-P6 -> 31 | P6: =IF(ISNUMBER(SEARCH("차감",AI6)), VALUE(SUBSTITUTE(SUBSTITUTE(SUBSTITUTE(TRIM(AI6)," ",""),"차감",""),"일","")), IF(AND(YEAR(F6)=$M$3,MONTH(F6)=$N$3),$O$3-DAY(F6), IF(AND(YEAR(E6)=$M$3,MONTH(E6)=$N$3),DAY(E6)-1,0))) -> 0 | Q6: =ROUNDDOWN(G6/$O$3*P6,-1) -> 0 | S6: =ROUNDDOWN(H6*R6,-1) -> 0 | T6: =G6-Q6-S6+N6+L6 -> 4369354.8 | U6: 1800000 | V6: 4 | W6: =A6 -> 1 | X6: =B6 -> 박은규 | Y6: =IF(T6<800000,0,(VLOOKUP(T6,'세액표(1202)'!A:L,V6+1))) -> 132410 | Z6: =ROUNDDOWN(Y6*10%,-1) -> 13240 | AA6: 209900 | AB6: =ROUNDDOWN(T6*3.595%,-1) -> 157070 | AC6: =ROUNDDOWN(AB6*13.14%,-1) -> 20630 | AD6: =ROUNDDOWN(T6*0.9%,-1) -> 39320 | AE6: =L6 -> 0 | AG6: =SUM(Y6:AF6) -> 572570 | AH6: =T6-AG6 -> 3796784.8 | AI6: =VLOOKUP(D6,'정직원 (2)'!$F$4:$M$90,8,0) -> 0.5추가 | AJ6: =DATEDIF(DATE(IF(VALUE(LEFT(D6,2))>22,1900,2000)+VALUE(LEFT(D6,2)),VALUE(MID(D6,3,2)),VALUE(MID(D6,5,2))),TODAY(),"Y") -> 38 | AK6: =_xlfn.LET( _xlpm.tag0, AI6, _xlpm.tag, TRIM(SUBSTITUTE(SUBSTITUTE(_xlpm.tag0," ",""),CHAR(160),"")), _xlpm.hasAdd, ISNUMBER(SEARCH("추가",_xlpm.tag)), _xlpm.hasSub, ISNUMBER(SEARCH("차감",_xlpm.tag)), _xlpm.rawText, SUBSTITUTE(SUBSTITUTE(_xlpm.tag,"추가",""),"차감",""), _xlpm.fac, IFERROR(VALUE(_xlpm.rawText),""), _xlpm.base, G6, _xlpm.denom, $O$3, _xlpm.expected, IF(_xlpm.hasAdd, _xlpm.base/_xlpm.denom*_xlpm.fac, IF(_xlpm.hasSub, ROUNDDOWN(_xlpm.base/_xlpm.denom*_xlpm.fac,-1),"")), _xlpm.tgt0, IF(_xlpm.hasSub, Q6, IF(_xlpm.hasAdd, N6, "")), _xlpm.tgt, IF(_xlpm.tgt0="","",IFERROR(1*SUBSTITUTE(_xlpm.tgt0,",",""),"")), _xlpm.diff, IF(AND(_xlpm.expected<>"",_xlpm.tgt<>""), _xlpm.tgt-_xlpm.expected,""), _xlpm.ok, IF(_xlpm.diff<>"", ABS(_xlpm.diff)<=1, FALSE), IF(_xlpm.tag="", "NO TAG", IF(NOT(OR(_xlpm.hasAdd,_xlpm.hasSub)), "INVALID TAG", IF(_xlpm.fac="", "BAD NUM", IF(_xlpm.tgt="", "NO VAL", IF(_xlpm.ok,"OK","NG: "&TEXT(_xlpm.diff,"#,##0")) ) ) ) ) ) -> OK | AL6: 5508064.5 | AO6: 7443333.3 | AP6: 4785483.9 | AQ6: 4114520 | AR6: 5015000 | AS6: 4646774.2 | AT6: 4300000 | AU6: 4508065 | AV6: 4453571.4 | AW6: 5008065 | AX6: =SUM(AM6:AW6) -> 44274813
A7: =ROW()-5 -> 2 | B7: piao jing | C7: =INDEX('정직원 (2)'!$B$4:$B$10,MATCH(임금대장!B7,'정직원 (2)'!$C$4:$C$10,0)) -> 롤 | D7: =VLOOKUP(B7,'정직원 (2)'!$C$4:$F$10,4,0) -> 830729-6100013 | E7: =VLOOKUP(B7,'정직원 (2)'!$C$4:$J$81,8,0) -> 44743 | F7: =VLOOKUP(B7,'정직원 (2)'!$C$4:$L$81,10,0) -> 0 | G7: =VLOOKUP(B7,'정직원 (2)'!$C$4:$F$81,3,0) -> 3400000 | H7: =ROUNDDOWN(G7/291,0) -> 11683 | I7: =ROUNDDOWN(($G7/291*209),0) -> 2441924 | J7: =ROUNDUP(($G7/291*65.2),0) -> 761787 | K7: =ROUNDUP(($G7/291*8.8),0) -> 102818 | L7: =VLOOKUP(B7,'정직원 (2)'!$C$4:$O$95,13,0) -> 0 | M7: =ROUNDUP(($G7/291*8),0) -> 93471 | N7: =IF(OR(AI7="",AI7=0),0, IF(ISNUMBER(SEARCH("추가",AI7)), G7/$O$3*VALUE(SUBSTITUTE(SUBSTITUTE(TRIM(AI7)," ",""),"추가","")), 0)) -> 274193.55 | O7: =$O$3-P7 -> 31 | P7: =IF(ISNUMBER(SEARCH("차감",AI7)), VALUE(SUBSTITUTE(SUBSTITUTE(SUBSTITUTE(TRIM(AI7)," ",""),"차감",""),"일","")), IF(AND(YEAR(F7)=$M$3,MONTH(F7)=$N$3),$O$3-DAY(F7), IF(AND(YEAR(E7)=$M$3,MONTH(E7)=$N$3),DAY(E7)-1,0))) -> 0 | Q7: =ROUNDDOWN(G7/$O$3*P7,-1) -> 0 | S7: =ROUNDDOWN(H7*R7,-1) -> 0 | T7: =G7-Q7-S7+N7+L7 -> 3674193.5 | U7: 1800000 | V7: 1 | W7: =A7 -> 2 | X7: =B7 -> piao jing | Y7: =IF(T7<800000,0,(VLOOKUP(T7,'세액표(1202)'!A:L,V7+1))) -> 144330 | Z7: =ROUNDDOWN(Y7*10%,-1) -> 14430 | AA7: 165630 | AB7: =ROUNDDOWN(T7*3.595%,-1) -> 132080 | AC7: =ROUNDDOWN(AB7*13.14%,-1) -> 17350 | AD7: =ROUNDDOWN(T7*0.9%,-1) -> 33060 | AE7: =L7 -> 0 | AG7: =SUM(Y7:AF7) -> 506880 | AH7: =T7-AG7 -> 3167313.5 | AI7: =VLOOKUP(D7,'정직원 (2)'!$F$4:$M$90,8,0) -> 2.5추가 | AJ7: =DATEDIF(DATE(IF(VALUE(LEFT(D7,2))>22,1900,2000)+VALUE(LEFT(D7,2)),VALUE(MID(D7,3,2)),VALUE(MID(D7,5,2))),TODAY(),"Y") -> 42 | AK7: =_xlfn.LET( _xlpm.tag0, AI7, _xlpm.tag, TRIM(SUBSTITUTE(SUBSTITUTE(_xlpm.tag0," ",""),CHAR(160),"")), _xlpm.hasAdd, ISNUMBER(SEARCH("추가",_xlpm.tag)), _xlpm.hasSub, ISNUMBER(SEARCH("차감",_xlpm.tag)), _xlpm.rawText, SUBSTITUTE(SUBSTITUTE(_xlpm.tag,"추가",""),"차감",""), _xlpm.fac, IFERROR(VALUE(_xlpm.rawText),""), _xlpm.base, G7, _xlpm.denom, $O$3, _xlpm.expected, IF(_xlpm.hasAdd, _xlpm.base/_xlpm.denom*_xlpm.fac, IF(_xlpm.hasSub, ROUNDDOWN(_xlpm.base/_xlpm.denom*_xlpm.fac,-1),"")), _xlpm.tgt0, IF(_xlpm.hasSub, Q7, IF(_xlpm.hasAdd, N7, "")), _xlpm.tgt, IF(_xlpm.tgt0="","",IFERROR(1*SUBSTITUTE(_xlpm.tgt0,",",""),"")), _xlpm.diff, IF(AND(_xlpm.expected<>"",_xlpm.tgt<>""), _xlpm.tgt-_xlpm.expected,""), _xlpm.ok, IF(_xlpm.diff<>"", ABS(_xlpm.diff)<=1, FALSE), IF(_xlpm.tag="", "NO TAG", IF(NOT(OR(_xlpm.hasAdd,_xlpm.hasSub)), "INVALID TAG", IF(_xlpm.fac="", "BAD NUM", IF(_xlpm.tgt="", "NO VAL", IF(_xlpm.ok,"OK","NG: "&TEXT(_xlpm.diff,"#,##0")) ) ) ) ) ) -> OK | AL7: 3564516.1 | AO7: 4013333.3 | AP7: 3564516.1 | AQ7: 3535490 | AR7: 3940000 | AS7: 3783871 | AT7: 3400000 | AU7: 3674194 | AV7: 3400000 | AW7: 3764517 | AX7: =SUM(AM7:AW7) -> 33075921
A8: =ROW()-5 -> 3 | B8: 박옥순 | C8: =INDEX('정직원 (2)'!$B$4:$B$10,MATCH(임금대장!B8,'정직원 (2)'!$C$4:$C$10,0)) -> 0 | D8: =VLOOKUP(B8,'정직원 (2)'!$C$4:$F$10,4,0) -> 630526-2252859 | E8: =VLOOKUP(B8,'정직원 (2)'!$C$4:$J$81,8,0) -> 45012 | F8: =VLOOKUP(B8,'정직원 (2)'!$C$4:$L$81,10,0) -> 0 | G8: =VLOOKUP(B8,'정직원 (2)'!$C$4:$F$81,3,0) -> 3300000 | H8: =ROUNDDOWN(G8/291,0) -> 11340 | I8: =ROUNDDOWN(($G8/291*209),0) -> 2370103 | J8: =ROUNDDOWN(($G8/291*65.2),0) -> 739381 | K8: =ROUNDUP(($G8/291*8.8),0) -> 99794 | L8: =VLOOKUP(B8,'정직원 (2)'!$C$4:$O$95,13,0) -> 0 | M8: =ROUNDUP(($G8/291*8),0) -> 90722 | N8: =IF(OR(AI8="",AI8=0),0, IF(ISNUMBER(SEARCH("추가",AI8)), G8/$O$3*VALUE(SUBSTITUTE(SUBSTITUTE(TRIM(AI8)," ",""),"추가","")), 0)) -> 53225.806 | O8: =$O$3-P8 -> 31 | P8: =IF(ISNUMBER(SEARCH("차감",AI8)), VALUE(SUBSTITUTE(SUBSTITUTE(SUBSTITUTE(TRIM(AI8)," ",""),"차감",""),"일","")), IF(AND(YEAR(F8)=$M$3,MONTH(F8)=$N$3),$O$3-DAY(F8), IF(AND(YEAR(E8)=$M$3,MONTH(E8)=$N$3),DAY(E8)-1,0))) -> 0 | Q8: =ROUNDDOWN(G8/$O$3*P8,-1) -> 0 | S8: =ROUNDDOWN(H8*R8,-1) -> 0 | T8: =G8-Q8-S8+N8+L8 -> 3353225.8 | V8: 1 | W8: =A8 -> 3 | X8: =B8 -> 박옥순 | Y8: =IF(T8<800000,0,(VLOOKUP(T8,'세액표(1202)'!A:L,V8+1))) -> 105210 | Z8: =ROUNDDOWN(Y8*10%,-1) -> 10520 | AB8: =ROUNDDOWN(T8*3.595%,-1) -> 120540 | AC8: =ROUNDDOWN(AB8*13.14%,-1) -> 15830 | AD8: =ROUNDDOWN(T8*0.9%,-1) -> 30170 | AE8: =L8 -> 0 | AG8: =SUM(Y8:AF8) -> 282270 | AH8: =T8-AG8 -> 3070955.8 | AI8: =VLOOKUP(D8,'정직원 (2)'!$F$4:$M$90,8,0) -> 0.5추가 | AJ8: =DATEDIF(DATE(IF(VALUE(LEFT(D8,2))>22,1900,2000)+VALUE(LEFT(D8,2)),VALUE(MID(D8,3,2)),VALUE(MID(D8,5,2))),TODAY(),"Y") -> 62 | AK8: =_xlfn.LET( _xlpm.tag0, AI8, _xlpm.tag, TRIM(SUBSTITUTE(SUBSTITUTE(_xlpm.tag0," ",""),CHAR(160),"")), _xlpm.hasAdd, ISNUMBER(SEARCH("추가",_xlpm.tag)), _xlpm.hasSub, ISNUMBER(SEARCH("차감",_xlpm.tag)), _xlpm.rawText, SUBSTITUTE(SUBSTITUTE(_xlpm.tag,"추가",""),"차감",""), _xlpm.fac, IFERROR(VALUE(_xlpm.rawText),""), _xlpm.base, G8, _xlpm.denom, $O$3, _xlpm.expected, IF(_xlpm.hasAdd, _xlpm.base/_xlpm.denom*_xlpm.fac, IF(_xlpm.hasSub, ROUNDDOWN(_xlpm.base/_xlpm.denom*_xlpm.fac,-1),"")), _xlpm.tgt0, IF(_xlpm.hasSub, Q8, IF(_xlpm.hasAdd, N8, "")), _xlpm.tgt, IF(_xlpm.tgt0="","",IFERROR(1*SUBSTITUTE(_xlpm.tgt0,",",""),"")), _xlpm.diff, IF(AND(_xlpm.expected<>"",_xlpm.tgt<>""), _xlpm.tgt-_xlpm.expected,""), _xlpm.ok, IF(_xlpm.diff<>"", ABS(_xlpm.diff)<=1, FALSE), IF(_xlpm.tag="", "NO TAG", IF(NOT(OR(_xlpm.hasAdd,_xlpm.hasSub)), "INVALID TAG", IF(_xlpm.fac="", "BAD NUM", IF(_xlpm.tgt="", "NO VAL", IF(_xlpm.ok,"OK","NG: "&TEXT(_xlpm.diff,"#,##0")) ) ) ) ) ) -> OK | AL8: 3459677.4 | AO8: 3300000 | AP8: 3353225.8 | AQ8: 3140330 | AR8: 3410000 | AS8: 3566129 | AT8: 3300000 | AU8: 3250000 | AV8: 3100000 | AW8: 3350000 | AX8: =SUM(AM8:AW8) -> 29769685
A9: =ROW()-5 -> 4 | B9: 김성환 | C9: =INDEX('정직원 (2)'!$B$4:$B$10,MATCH(임금대장!B9,'정직원 (2)'!$C$4:$C$10,0)) -> 핫 | D9: =VLOOKUP(B9,'정직원 (2)'!$C$4:$F$10,4,0) -> 970504-1019024 | E9: =VLOOKUP(B9,'정직원 (2)'!$C$4:$J$81,8,0) -> 45278 | F9: =VLOOKUP(B9,'정직원 (2)'!$C$4:$L$81,10,0) -> 0 | G9: =VLOOKUP(B9,'정직원 (2)'!$C$4:$F$81,3,0) -> 3500000 | H9: =ROUNDDOWN(G9/291,0) -> 12027 | I9: =ROUNDDOWN(($G9/291*209),0) -> 2513745 | J9: =ROUNDUP(($G9/291*65.2),0) -> 784193 | K9: =ROUNDUP(($G9/291*8.8),0) -> 105842 | L9: =VLOOKUP(B9,'정직원 (2)'!$C$4:$O$95,13,0) -> 0 | M9: =ROUNDUP(($G9/291*8),0) -> 96220 | N9: =IF(OR(AI9="",AI9=0),0, IF(ISNUMBER(SEARCH("추가",AI9)), G9/$O$3*VALUE(SUBSTITUTE(SUBSTITUTE(TRIM(AI9)," ",""),"추가","")), 0)) -> 282258.06 | O9: =$O$3-P9 -> 31 | P9: =IF(ISNUMBER(SEARCH("차감",AI9)), VALUE(SUBSTITUTE(SUBSTITUTE(SUBSTITUTE(TRIM(AI9)," ",""),"차감",""),"일","")), IF(AND(YEAR(F9)=$M$3,MONTH(F9)=$N$3),$O$3-DAY(F9), IF(AND(YEAR(E9)=$M$3,MONTH(E9)=$N$3),DAY(E9)-1,0))) -> 0 | Q9: =ROUNDDOWN(G9/$O$3*P9,-1) -> 0 | S9: =ROUNDDOWN(H9*R9,-1) -> 0 | T9: =G9-Q9-S9+N9+L9 -> 3782258.1 | U9: 1800000 | V9: 1 | W9: =A9 -> 4 | X9: =B9 -> 김성환 | Y9: =IF(T9<800000,0,(VLOOKUP(T9,'세액표(1202)'!A:L,V9+1))) -> 163920 | Z9: =ROUNDDOWN(Y9*10%,-1) -> 16390 | AA9: 169950 | AB9: =ROUNDDOWN(T9*3.595%,-1) -> 135970 | AC9: =ROUNDDOWN(AB9*13.14%,-1) -> 17860 | AD9: =ROUNDDOWN(T9*0.9%,-1) -> 34040 | AE9: =L9 -> 0 | AG9: =SUM(Y9:AF9) -> 538130 | AH9: =T9-AG9 -> 3244128.1 | AI9: =VLOOKUP(D9,'정직원 (2)'!$F$4:$M$90,8,0) -> 2.5추가 | AJ9: =DATEDIF(DATE(IF(VALUE(LEFT(D9,2))>22,1900,2000)+VALUE(LEFT(D9,2)),VALUE(MID(D9,3,2)),VALUE(MID(D9,5,2))),TODAY(),"Y") -> 28 | AK9: =_xlfn.LET( _xlpm.tag0, AI9, _xlpm.tag, TRIM(SUBSTITUTE(SUBSTITUTE(_xlpm.tag0," ",""),CHAR(160),"")), _xlpm.hasAdd, ISNUMBER(SEARCH("추가",_xlpm.tag)), _xlpm.hasSub, ISNUMBER(SEARCH("차감",_xlpm.tag)), _xlpm.rawText, SUBSTITUTE(SUBSTITUTE(_xlpm.tag,"추가",""),"차감",""), _xlpm.fac, IFERROR(VALUE(_xlpm.rawText),""), _xlpm.base, G9, _xlpm.denom, $O$3, _xlpm.expected, IF(_xlpm.hasAdd, _xlpm.base/_xlpm.denom*_xlpm.fac, IF(_xlpm.hasSub, ROUNDDOWN(_xlpm.base/_xlpm.denom*_xlpm.fac,-1),"")), _xlpm.tgt0, IF(_xlpm.hasSub, Q9, IF(_xlpm.hasAdd, N9, "")), _xlpm.tgt, IF(_xlpm.tgt0="","",IFERROR(1*SUBSTITUTE(_xlpm.tgt0,",",""),"")), _xlpm.diff, IF(AND(_xlpm.expected<>"",_xlpm.tgt<>""), _xlpm.tgt-_xlpm.expected,""), _xlpm.ok, IF(_xlpm.diff<>"", ABS(_xlpm.diff)<=1, FALSE), IF(_xlpm.tag="", "NO TAG", IF(NOT(OR(_xlpm.hasAdd,_xlpm.hasSub)), "INVALID TAG", IF(_xlpm.fac="", "BAD NUM", IF(_xlpm.tgt="", "NO VAL", IF(_xlpm.ok,"OK","NG: "&TEXT(_xlpm.diff,"#,##0")) ) ) ) ) ) -> OK | AL9: 3669354.8 | AO9: 4200000 | AP9: 3500000 | AQ9: 3630650 | AR9: 4050000 | AS9: 3895161.3 | AT9: 3500000 | AU9: 3556452 | AV9: 3500000 | AW9: 3969355 | AX9: =SUM(AM9:AW9) -> 33801618
A10: =ROW()-5 -> 5 | B10: 강수정 | C10: =INDEX('정직원 (2)'!$B$4:$B$10,MATCH(임금대장!B10,'정직원 (2)'!$C$4:$C$10,0)) -> 핫 | D10: =VLOOKUP(B10,'정직원 (2)'!$C$4:$F$10,4,0) -> 970726-2155815 | E10: =VLOOKUP(B10,'정직원 (2)'!$C$4:$J$81,8,0) -> 45369 | F10: =VLOOKUP(B10,'정직원 (2)'!$C$4:$L$81,10,0) -> 0 | G10: =VLOOKUP(B10,'정직원 (2)'!$C$4:$F$81,3,0) -> 3500000 | H10: =ROUNDDOWN(G10/291,0) -> 12027 | I10: =ROUNDDOWN(($G10/291*209),0) -> 2513745 | J10: =ROUNDUP(($G10/291*65.2),0) -> 784193 | K10: =ROUNDUP(($G10/291*8.8),0) -> 105842 | L10: =VLOOKUP(B10,'정직원 (2)'!$C$4:$O$95,13,0) -> 0 | M10: =ROUNDUP(($G10/291*8),0) -> 96220 | N10: =IF(OR(AI10="",AI10=0),0, IF(ISNUMBER(SEARCH("추가",AI10)), G10/$O$3*VALUE(SUBSTITUTE(SUBSTITUTE(TRIM(AI10)," ",""),"추가","")), 0)) -> 169354.84 | O10: =$O$3-P10 -> 31 | P10: =IF(ISNUMBER(SEARCH("차감",AI10)), VALUE(SUBSTITUTE(SUBSTITUTE(SUBSTITUTE(TRIM(AI10)," ",""),"차감",""),"일","")), IF(AND(YEAR(F10)=$M$3,MONTH(F10)=$N$3),$O$3-DAY(F10), IF(AND(YEAR(E10)=$M$3,MONTH(E10)=$N$3),DAY(E10)-1,0))) -> 0 | Q10: =ROUNDDOWN(G10/$O$3*P10,-1) -> 0 | S10: =ROUNDDOWN(H10*R10,-1) -> 0 | T10: =G10-Q10-S10+N10+L10 -> 3669354.8 | U10: 1800000 | V10: 1 | W10: =A10 -> 5 | X10: =B10 -> 강수정 | Y10: =IF(T10<800000,0,(VLOOKUP(T10,'세액표(1202)'!A:L,V10+1))) -> 144330 | Z10: =ROUNDDOWN(Y10*10%,-1) -> 14430 | AA10: 154890 | AB10: =ROUNDDOWN(T10*3.595%,-1) -> 131910 | AC10: =ROUNDDOWN(AB10*13.14%,-1) -> 17330 | AD10: =ROUNDDOWN(T10*0.9%,-1) -> 33020 | AE10: =L10 -> 0 | AG10: =SUM(Y10:AF10) -> 495910 | AH10: =T10-AG10 -> 3173444.8 | AI10: =VLOOKUP(D10,'정직원 (2)'!$F$4:$M$90,8,0) -> 1.5추가 | AJ10: =DATEDIF(DATE(IF(VALUE(LEFT(D10,2))>22,1900,2000)+VALUE(LEFT(D10,2)),VALUE(MID(D10,3,2)),VALUE(MID(D10,5,2))),TODAY(),"Y") -> 28 | AK10: =_xlfn.LET( _xlpm.tag0, AI10, _xlpm.tag, TRIM(SUBSTITUTE(SUBSTITUTE(_xlpm.tag0," ",""),CHAR(160),"")), _xlpm.hasAdd, ISNUMBER(SEARCH("추가",_xlpm.tag)), _xlpm.hasSub, ISNUMBER(SEARCH("차감",_xlpm.tag)), _xlpm.rawText, SUBSTITUTE(SUBSTITUTE(_xlpm.tag,"추가",""),"차감",""), _xlpm.fac, IFERROR(VALUE(_xlpm.rawText),""), _xlpm.base, G10, _xlpm.denom, $O$3, _xlpm.expected, IF(_xlpm.hasAdd, _xlpm.base/_xlpm.denom*_xlpm.fac, IF(_xlpm.hasSub, ROUNDDOWN(_xlpm.base/_xlpm.denom*_xlpm.fac,-1),"")), _xlpm.tgt0, IF(_xlpm.hasSub, Q10, IF(_xlpm.hasAdd, N10, "")), _xlpm.tgt, IF(_xlpm.tgt0="","",IFERROR(1*SUBSTITUTE(_xlpm.tgt0,",",""),"")), _xlpm.diff, IF(AND(_xlpm.expected<>"",_xlpm.tgt<>""), _xlpm.tgt-_xlpm.expected,""), _xlpm.ok, IF(_xlpm.diff<>"", ABS(_xlpm.diff)<=1, FALSE), IF(_xlpm.tag="", "NO TAG", IF(NOT(OR(_xlpm.hasAdd,_xlpm.hasSub)), "INVALID TAG", IF(_xlpm.fac="", "BAD NUM", IF(_xlpm.tgt="", "NO VAL", IF(_xlpm.ok,"OK","NG: "&TEXT(_xlpm.diff,"#,##0")) ) ) ) ) ) -> OK | AL10: 3669354.8 | AO10: 4100000 | AP10: 3400000 | AQ10: 3333880 | AR10: 3720000 | AS10: 3566129 | AT10: 3410000 | AU10: 3251613 | AV10: 3200000 | AW10: 3654839 | AX10: =SUM(AM10:AW10) -> 31636461
A11: =ROW()-5 -> 6 | B11: 장준수 | C11: =INDEX('정직원 (2)'!$B$4:$B$10,MATCH(임금대장!B11,'정직원 (2)'!$C$4:$C$10,0)) -> 홀 | D11: =VLOOKUP(B11,'정직원 (2)'!$C$4:$F$10,4,0) -> 890417-1709714 | E11: =VLOOKUP(B11,'정직원 (2)'!$C$4:$J$81,8,0) -> 45355 | F11: =VLOOKUP(B11,'정직원 (2)'!$C$4:$L$81,10,0) -> 0 | G11: =VLOOKUP(B11,'정직원 (2)'!$C$4:$F$81,3,0) -> 3500000 | H11: =ROUNDDOWN(G11/291,0) -> 12027 | I11: =ROUNDDOWN(($G11/291*209),0) -> 2513745 | J11: =ROUNDUP(($G11/291*65.2),0) -> 784193 | K11: =ROUNDUP(($G11/291*8.8),0) -> 105842 | L11: =VLOOKUP(B11,'정직원 (2)'!$C$4:$O$95,13,0) -> 0 | M11: =ROUNDUP(($G11/291*8),0) -> 96220 | N11: =IF(OR(AI11="",AI11=0),0, IF(ISNUMBER(SEARCH("추가",AI11)), G11/$O$3*VALUE(SUBSTITUTE(SUBSTITUTE(TRIM(AI11)," ",""),"추가","")), 0)) -> 169354.84 | O11: =$O$3-P11 -> 31 | P11: =IF(ISNUMBER(SEARCH("차감",AI11)), VALUE(SUBSTITUTE(SUBSTITUTE(SUBSTITUTE(TRIM(AI11)," ",""),"차감",""),"일","")), IF(AND(YEAR(F11)=$M$3,MONTH(F11)=$N$3),$O$3-DAY(F11), IF(AND(YEAR(E11)=$M$3,MONTH(E11)=$N$3),DAY(E11)-1,0))) -> 0 | Q11: =ROUNDDOWN(G11/$O$3*P11,-1) -> 0 | S11: =ROUNDDOWN(H11*R11,-1) -> 0 | T11: =G11-Q11-S11+N11+L11 -> 3669354.8 | U11: 1800000 | V11: 1 | W11: =A11 -> 6 | X11: =B11 -> 장준수 | Y11: =IF(T11<800000,0,(VLOOKUP(T11,'세액표(1202)'!A:L,V11+1))) -> 144330 | Z11: =ROUNDDOWN(Y11*10%,-1) -> 14430 | AA11: 163210 | AB11: =ROUNDDOWN(T11*3.595%,-1) -> 131910 | AC11: =ROUNDDOWN(AB11*13.14%,-1) -> 17330 | AD11: =ROUNDDOWN(T11*0.9%,-1) -> 33020 | AE11: =L11 -> 0 | AG11: =SUM(Y11:AF11) -> 504230 | AH11: =T11-AG11 -> 3165124.8 | AI11: =VLOOKUP(D11,'정직원 (2)'!$F$4:$M$90,8,0) -> 1.5추가 | AJ11: =DATEDIF(DATE(IF(VALUE(LEFT(D11,2))>22,1900,2000)+VALUE(LEFT(D11,2)),VALUE(MID(D11,3,2)),VALUE(MID(D11,5,2))),TODAY(),"Y") -> 36 | AK11: =_xlfn.LET( _xlpm.tag0, AI11, _xlpm.tag, TRIM(SUBSTITUTE(SUBSTITUTE(_xlpm.tag0," ",""),CHAR(160),"")), _xlpm.hasAdd, ISNUMBER(SEARCH("추가",_xlpm.tag)), _xlpm.hasSub, ISNUMBER(SEARCH("차감",_xlpm.tag)), _xlpm.rawText, SUBSTITUTE(SUBSTITUTE(_xlpm.tag,"추가",""),"차감",""), _xlpm.fac, IFERROR(VALUE(_xlpm.rawText),""), _xlpm.base, G11, _xlpm.denom, $O$3, _xlpm.expected, IF(_xlpm.hasAdd, _xlpm.base/_xlpm.denom*_xlpm.fac, IF(_xlpm.hasSub, ROUNDDOWN(_xlpm.base/_xlpm.denom*_xlpm.fac,-1),"")), _xlpm.tgt0, IF(_xlpm.hasSub, Q11, IF(_xlpm.hasAdd, N11, "")), _xlpm.tgt, IF(_xlpm.tgt0="","",IFERROR(1*SUBSTITUTE(_xlpm.tgt0,",",""),"")), _xlpm.diff, IF(AND(_xlpm.expected<>"",_xlpm.tgt<>""), _xlpm.tgt-_xlpm.expected,""), _xlpm.ok, IF(_xlpm.diff<>"", ABS(_xlpm.diff)<=1, FALSE), IF(_xlpm.tag="", "NO TAG", IF(NOT(OR(_xlpm.hasAdd,_xlpm.hasSub)), "INVALID TAG", IF(_xlpm.fac="", "BAD NUM", IF(_xlpm.tgt="", "NO VAL", IF(_xlpm.ok,"OK","NG: "&TEXT(_xlpm.diff,"#,##0")) ) ) ) ) ) -> OK | AL11: 3969354.8 | AO11: 3975000 | AP11: 3838709.7 | AQ11: 3330650 | AR11: 4108333.3 | AS11: 4008064.5 | AT11: 3616666.7 | AU11: 3782258 | AV11: 3625000 | AW11: 3856452 | AX11: =SUM(AM11:AW11) -> 34141134
A12: =ROW()-5 -> 7 | B12: 강정애 | C12: =INDEX('정직원 (2)'!$B$4:$B$10,MATCH(임금대장!B12,'정직원 (2)'!$C$4:$C$10,0)) -> 샐러드 | D12: =VLOOKUP(B12,'정직원 (2)'!$C$4:$F$10,4,0) -> 621005-6100899 | E12: 45484 | F12: =VLOOKUP(B12,'정직원 (2)'!$C$4:$L$81,10,0) -> 0 | G12: =VLOOKUP(B12,'정직원 (2)'!$C$4:$F$81,3,0) -> 3300000 | H12: =ROUNDDOWN(G12/291,0) -> 11340 | I12: =ROUNDDOWN(($G12/291*209),0) -> 2370103 | J12: =ROUNDUP(($G12/291*65.2),0) -> 739382 | K12: =ROUNDUP(($G12/291*8.8),0) -> 99794 | L12: =VLOOKUP(B12,'정직원 (2)'!$C$4:$O$95,13,0) -> 0 | M12: =ROUNDUP(($G12/291*8),0) -> 90722 | N12: =IF(OR(AI12="",AI12=0),0, IF(ISNUMBER(SEARCH("추가",AI12)), G12/$O$3*VALUE(SUBSTITUTE(SUBSTITUTE(TRIM(AI12)," ",""),"추가","")), 0)) -> 53225.806 | O12: =$O$3-P12 -> 31 | P12: =IF(ISNUMBER(SEARCH("차감",AI12)), VALUE(SUBSTITUTE(SUBSTITUTE(SUBSTITUTE(TRIM(AI12)," ",""),"차감",""),"일","")), IF(AND(YEAR(F12)=$M$3,MONTH(F12)=$N$3),$O$3-DAY(F12), IF(AND(YEAR(E12)=$M$3,MONTH(E12)=$N$3),DAY(E12)-1,0))) -> 0 | Q12: =ROUNDDOWN(G12/$O$3*P12,-1) -> 0 | S12: =ROUNDDOWN(H12*R12,-1) -> 0 | T12: =G12-Q12-S12+N12+L12 -> 3353225.8 | U12: 1800000 | V12: 1 | W12: =A12 -> 7 | X12: =B12 -> 강정애 | Y12: =IF(T12<800000,0,(VLOOKUP(T12,'세액표(1202)'!A:L,V12+1))) -> 105210 | Z12: =ROUNDDOWN(Y12*10%,-1) -> 10520 | AB12: =ROUNDDOWN(T12*3.595%,-1) -> 120540 | AC12: =ROUNDDOWN(AB12*13.14%,-1) -> 15830 | AD12: =ROUNDDOWN(T12*0.9%,-1) -> 30170 | AE12: =L12 -> 0 | AG12: =SUM(Y12:AF12) -> 282270 | AH12: =T12-AG12 -> 3070955.8 | AI12: =VLOOKUP(D12,'정직원 (2)'!$F$4:$M$90,8,0) -> 0.5추가 | AJ12: =DATEDIF(DATE(IF(VALUE(LEFT(D12,2))>22,1900,2000)+VALUE(LEFT(D12,2)),VALUE(MID(D12,3,2)),VALUE(MID(D12,5,2))),TODAY(),"Y") -> 63 | AK12: =_xlfn.LET( _xlpm.tag0, AI12, _xlpm.tag, TRIM(SUBSTITUTE(SUBSTITUTE(_xlpm.tag0," ",""),CHAR(160),"")), _xlpm.hasAdd, ISNUMBER(SEARCH("추가",_xlpm.tag)), _xlpm.hasSub, ISNUMBER(SEARCH("차감",_xlpm.tag)), _xlpm.rawText, SUBSTITUTE(SUBSTITUTE(_xlpm.tag,"추가",""),"차감",""), _xlpm.fac, IFERROR(VALUE(_xlpm.rawText),""), _xlpm.base, G12, _xlpm.denom, $O$3, _xlpm.expected, IF(_xlpm.hasAdd, _xlpm.base/_xlpm.denom*_xlpm.fac, IF(_xlpm.hasSub, ROUNDDOWN(_xlpm.base/_xlpm.denom*_xlpm.fac,-1),"")), _xlpm.tgt0, IF(_xlpm.hasSub, Q12, IF(_xlpm.hasAdd, N12, "")), _xlpm.tgt, IF(_xlpm.tgt0="","",IFERROR(1*SUBSTITUTE(_xlpm.tgt0,",",""),"")), _xlpm.diff, IF(AND(_xlpm.expected<>"",_xlpm.tgt<>""), _xlpm.tgt-_xlpm.expected,""), _xlpm.ok, IF(_xlpm.diff<>"", ABS(_xlpm.diff)<=1, FALSE), IF(_xlpm.tag="", "NO TAG", IF(NOT(OR(_xlpm.hasAdd,_xlpm.hasSub)), "INVALID TAG", IF(_xlpm.fac="", "BAD NUM", IF(_xlpm.tgt="", "NO VAL", IF(_xlpm.ok,"OK","NG: "&TEXT(_xlpm.diff,"#,##0")) ) ) ) ) ) -> OK | AL12: 3353225.8 | AO12: 3300000 | AP12: 3353225.8 | AQ12: 3440330 | AR12: 3610000 | AS12: 3459677.4 | AT12: 3300000 | AU12: 3354839 | AV12: 3200000 | AW12: 3451613 | AX12: =SUM(AM12:AW12) -> 30469685
A13: =ROW()-5 -> 8 | B13: 김금희 | C13: =INDEX('정직원 (2)'!$B$4:$B$20,MATCH(임금대장!B13,'정직원 (2)'!$C$4:$C$20,0)) -> 0 | D13: =VLOOKUP(B13,'정직원 (2)'!$C$4:$F$20,4,0) -> 700318-2018314 | E13: =VLOOKUP(B13,'정직원 (2)'!$C$4:$J$81,8,0) -> 45499 | F13: =VLOOKUP(B13,'정직원 (2)'!$C$4:$L$81,10,0) -> 0 | G13: =VLOOKUP(B13,'정직원 (2)'!$C$4:$F$81,3,0) -> 2300000 | H13: =ROUNDDOWN(G13/217,0) -> 10599 | I13: =ROUNDDOWN(($G13/291*209),0) -> 1651890 | J13: =ROUNDDOWN(($G13/291*65.2),0) -> 515326 | K13: =ROUNDUP(($G13/291*8.8),0) -> 69554 | L13: =VLOOKUP(B13,'정직원 (2)'!$C$4:$O$95,13,0) -> 0 | M13: =ROUNDDOWN(($G13/291*8),0) -> 63230 | N13: =IF(OR(AI13="",AI13=0),0, IF(ISNUMBER(SEARCH("추가",AI13)), G13/$O$3*VALUE(SUBSTITUTE(SUBSTITUTE(TRIM(AI13)," ",""),"추가","")), 0)) -> 37096.774 | O13: =$O$3-P13 -> 31 | P13: =IF(ISNUMBER(SEARCH("차감",AI13)), VALUE(SUBSTITUTE(SUBSTITUTE(SUBSTITUTE(TRIM(AI13)," ",""),"차감",""),"일","")), IF(AND(YEAR(F13)=$M$3,MONTH(F13)=$N$3),$O$3-DAY(F13), IF(AND(YEAR(E13)=$M$3,MONTH(E13)=$N$3),DAY(E13)-1,0))) -> 0 | Q13: =ROUNDDOWN(G13/$O$3*P13,-1) -> 0 | S13: =ROUNDDOWN(H13*R13,-1) -> 0 | T13: =G13-Q13-S13+N13+L13 -> 2337096.8 | U13: 1800000 | V13: 1 | W13: =A13 -> 8 | X13: =B13 -> 김금희 | Y13: =IF(T13<800000,0,(VLOOKUP(T13,'세액표(1202)'!A:L,V13+1))) -> 29810 | Z13: =ROUNDDOWN(Y13*10%,-1) -> 2980 | AA13: 112290 | AB13: =ROUNDDOWN(T13*3.595%,-1) -> 84010 | AC13: =ROUNDDOWN(AB13*13.14%,-1) -> 11030 | AD13: =ROUNDDOWN(T13*0.9%,-1) -> 21030 | AE13: =L13 -> 0 | AG13: =SUM(Y13:AF13) -> 261150 | AH13: =T13-AG13 -> 2075946.8 | AI13: =VLOOKUP(D13,'정직원 (2)'!$F$4:$M$90,8,0) -> 0.5추가 | AJ13: =DATEDIF(DATE(IF(VALUE(LEFT(D13,2))>22,1900,2000)+VALUE(LEFT(D13,2)),VALUE(MID(D13,3,2)),VALUE(MID(D13,5,2))),TODAY(),"Y") -> 55 | AK13: =_xlfn.LET( _xlpm.tag0, AI13, _xlpm.tag, TRIM(SUBSTITUTE(SUBSTITUTE(_xlpm.tag0," ",""),CHAR(160),"")), _xlpm.hasAdd, ISNUMBER(SEARCH("추가",_xlpm.tag)), _xlpm.hasSub, ISNUMBER(SEARCH("차감",_xlpm.tag)), _xlpm.rawText, SUBSTITUTE(SUBSTITUTE(_xlpm.tag,"추가",""),"차감",""), _xlpm.fac, IFERROR(VALUE(_xlpm.rawText),""), _xlpm.base, G13, _xlpm.denom, $O$3, _xlpm.expected, IF(_xlpm.hasAdd, _xlpm.base/_xlpm.denom*_xlpm.fac, IF(_xlpm.hasSub, ROUNDDOWN(_xlpm.base/_xlpm.denom*_xlpm.fac,-1),"")), _xlpm.tgt0, IF(_xlpm.hasSub, Q13, IF(_xlpm.hasAdd, N13, "")), _xlpm.tgt, IF(_xlpm.tgt0="","",IFERROR(1*SUBSTITUTE(_xlpm.tgt0,",",""),"")), _xlpm.diff, IF(AND(_xlpm.expected<>"",_xlpm.tgt<>""), _xlpm.tgt-_xlpm.expected,""), _xlpm.ok, IF(_xlpm.diff<>"", ABS(_xlpm.diff)<=1, FALSE), IF(_xlpm.tag="", "NO TAG", IF(NOT(OR(_xlpm.hasAdd,_xlpm.hasSub)), "INVALID TAG", IF(_xlpm.fac="", "BAD NUM", IF(_xlpm.tgt="", "NO VAL", IF(_xlpm.ok,"OK","NG: "&TEXT(_xlpm.diff,"#,##0")) ) ) ) ) ) -> OK | AL13: 2337096.8 | AO13: 2300000 | AP13: 2337096.8 | AQ13: 2114520 | AR13: 2376666.7 | AS13: 2411290.3 | AT13: 2300000 | AU13: 2337097 | AV13: 2300000 | AW13: 2537097 | AX13: =SUM(AM13:AW13) -> 21013768
A14: =ROW()-5 -> 9 | B14: 서헌규 | C14: =INDEX('정직원 (2)'!$B$4:$B$20,MATCH(임금대장!B14,'정직원 (2)'!$C$4:$C$20,0)) -> 0 | D14: =VLOOKUP(B14,'정직원 (2)'!$C$4:$F$20,4,0) -> 921204-1748215 | E14: =VLOOKUP(B14,'정직원 (2)'!$C$4:$J$81,8,0) -> 45502 | F14: =VLOOKUP(B14,'정직원 (2)'!$C$4:$L$81,10,0) -> 0 | G14: =VLOOKUP(B14,'정직원 (2)'!$C$4:$F$81,3,0) -> 3400000 | H14: =ROUNDDOWN(G14/291,0) -> 11683 | I14: =ROUNDDOWN(($G14/291*209),0) -> 2441924 | J14: =ROUNDUP(($G14/291*65.2),0) -> 761787 | K14: =ROUNDUP(($G14/291*8.8),0) -> 102818 | L14: =VLOOKUP(B14,'정직원 (2)'!$C$4:$O$95,13,0) -> 0 | M14: =ROUNDUP(($G14/291*8),0) -> 93471 | N14: =IF(OR(AI14="",AI14=0),0, IF(ISNUMBER(SEARCH("추가",AI14)), G14/$O$3*VALUE(SUBSTITUTE(SUBSTITUTE(TRIM(AI14)," ",""),"추가","")), 0)) -> 164516.13 | O14: =$O$3-P14 -> 31 | P14: =IF(ISNUMBER(SEARCH("차감",AI14)), VALUE(SUBSTITUTE(SUBSTITUTE(SUBSTITUTE(TRIM(AI14)," ",""),"차감",""),"일","")), IF(AND(YEAR(F14)=$M$3,MONTH(F14)=$N$3),$O$3-DAY(F14), IF(AND(YEAR(E14)=$M$3,MONTH(E14)=$N$3),DAY(E14)-1,0))) -> 0 | Q14: =ROUNDDOWN(G14/$O$3*P14,-1) -> 0 | S14: =ROUNDDOWN(H14*R14,-1) -> 0 | T14: =G14-Q14-S14+N14+L14 -> 3564516.1 | U14: 1800000 | V14: 1 | W14: =A14 -> 9 | X14: =B14 -> 서헌규 | Y14: =IF(T14<800000,0,(VLOOKUP(T14,'세액표(1202)'!A:L,V14+1))) -> 132110 | Z14: =ROUNDDOWN(Y14*10%,-1) -> 13210 | AA14: 160020 | AB14: =ROUNDDOWN(T14*3.595%,-1) -> 128140 | AC14: =ROUNDDOWN(AB14*13.14%,-1) -> 16830 | AD14: =ROUNDDOWN(T14*0.9%,-1) -> 32080 | AE14: =L14 -> 0 | AG14: =SUM(Y14:AF14) -> 482390 | AH14: =T14-AG14 -> 3082126.1 | AI14: =VLOOKUP(D14,'정직원 (2)'!$F$4:$M$90,8,0) -> 1.5추가 | AJ14: =DATEDIF(DATE(IF(VALUE(LEFT(D14,2))>22,1900,2000)+VALUE(LEFT(D14,2)),VALUE(MID(D14,3,2)),VALUE(MID(D14,5,2))),TODAY(),"Y") -> 33 | AK14: =_xlfn.LET( _xlpm.tag0, AI14, _xlpm.tag, TRIM(SUBSTITUTE(SUBSTITUTE(_xlpm.tag0," ",""),CHAR(160),"")), _xlpm.hasAdd, ISNUMBER(SEARCH("추가",_xlpm.tag)), _xlpm.hasSub, ISNUMBER(SEARCH("차감",_xlpm.tag)), _xlpm.rawText, SUBSTITUTE(SUBSTITUTE(_xlpm.tag,"추가",""),"차감",""), _xlpm.fac, IFERROR(VALUE(_xlpm.rawText),""), _xlpm.base, G14, _xlpm.denom, $O$3, _xlpm.expected, IF(_xlpm.hasAdd, _xlpm.base/_xlpm.denom*_xlpm.fac, IF(_xlpm.hasSub, ROUNDDOWN(_xlpm.base/_xlpm.denom*_xlpm.fac,-1),"")), _xlpm.tgt0, IF(_xlpm.hasSub, Q14, IF(_xlpm.hasAdd, N14, "")), _xlpm.tgt, IF(_xlpm.tgt0="","",IFERROR(1*SUBSTITUTE(_xlpm.tgt0,",",""),"")), _xlpm.diff, IF(AND(_xlpm.expected<>"",_xlpm.tgt<>""), _xlpm.tgt-_xlpm.expected,""), _xlpm.ok, IF(_xlpm.diff<>"", ABS(_xlpm.diff)<=1, FALSE), IF(_xlpm.tag="", "NO TAG", IF(NOT(OR(_xlpm.hasAdd,_xlpm.hasSub)), "INVALID TAG", IF(_xlpm.fac="", "BAD NUM", IF(_xlpm.tgt="", "NO VAL", IF(_xlpm.ok,"OK","NG: "&TEXT(_xlpm.diff,"#,##0")) ) ) ) ) ) -> OK | AL14: 3454838.7 | AO14: 3410000 | AP14: 3566129 | AQ14: 3045170 | AR14: 3520000 | AS14: 3561290.3 | AT14: 3200000 | AU14: 3354839 | AV14: 3314285.7 | AW14: 3551613 | AX14: =SUM(AM14:AW14) -> 30523327
A15: =ROW()-5 -> 10 | B15: 김선월 | C15: =INDEX('정직원 (2)'!$B$4:$B$20,MATCH(임금대장!B15,'정직원 (2)'!$C$4:$C$20,0)) -> 샐러드 | D15: =VLOOKUP(B15,'정직원 (2)'!$C$4:$F$20,4,0) -> 631004-6320198 | E15: =VLOOKUP(B15,'정직원 (2)'!$C$4:$J$81,8,0) -> 45610 | F15: =VLOOKUP(B15,'정직원 (2)'!$C$4:$L$81,10,0) -> 0 | G15: =VLOOKUP(B15,'정직원 (2)'!$C$4:$F$81,3,0) -> 3300000 | H15: =ROUNDDOWN(G15/291,0) -> 11340 | I15: =ROUNDDOWN(($G15/291*209),0) -> 2370103 | J15: =ROUNDDOWN(($G15/291*65.2),0) -> 739381 | K15: =ROUNDUP(($G15/291*8.8),0) -> 99794 | L15: =VLOOKUP(B15,'정직원 (2)'!$C$4:$O$95,13,0) -> 0 | M15: =ROUNDUP(($G15/291*8),0) -> 90722 | N15: =IF(OR(AI15="",AI15=0),0, IF(ISNUMBER(SEARCH("추가",AI15)), G15/$O$3*VALUE(SUBSTITUTE(SUBSTITUTE(TRIM(AI15)," ",""),"추가","")), 0)) -> 53225.806 | O15: =$O$3-P15 -> 31 | P15: =IF(ISNUMBER(SEARCH("차감",AI15)), VALUE(SUBSTITUTE(SUBSTITUTE(SUBSTITUTE(TRIM(AI15)," ",""),"차감",""),"일","")), IF(AND(YEAR(F15)=$M$3,MONTH(F15)=$N$3),$O$3-DAY(F15), IF(AND(YEAR(E15)=$M$3,MONTH(E15)=$N$3),DAY(E15)-1,0))) -> 0 | Q15: =ROUNDDOWN(G15/$O$3*P15,-1) -> 0 | S15: =ROUNDDOWN(H15*R15,-1) -> 0 | T15: =G15-Q15-S15+N15+L15 -> 3353225.8 | U15: 1800000 | V15: 1 | W15: =A15 -> 10 | X15: =B15 -> 김선월 | Y15: =IF(T15<800000,0,(VLOOKUP(T15,'세액표(1202)'!A:L,V15+1))) -> 105210 | Z15: =ROUNDDOWN(Y15*10%,-1) -> 10520 | AB15: =ROUNDDOWN(T15*3.595%,-1) -> 120540 | AC15: =ROUNDDOWN(AB15*13.14%,-1) -> 15830 | AE15: =L15 -> 0 | AG15: =SUM(Y15:AF15) -> 252100 | AH15: =T15-AG15 -> 3101125.8 | AI15: =VLOOKUP(D15,'정직원 (2)'!$F$4:$M$90,8,0) -> 0.5추가 | AJ15: =DATEDIF(DATE(IF(VALUE(LEFT(D15,2))>22,1900,2000)+VALUE(LEFT(D15,2)),VALUE(MID(D15,3,2)),VALUE(MID(D15,5,2))),TODAY(),"Y") -> 62 | AK15: =_xlfn.LET( _xlpm.tag0, AI15, _xlpm.tag, TRIM(SUBSTITUTE(SUBSTITUTE(_xlpm.tag0," ",""),CHAR(160),"")), _xlpm.hasAdd, ISNUMBER(SEARCH("추가",_xlpm.tag)), _xlpm.hasSub, ISNUMBER(SEARCH("차감",_xlpm.tag)), _xlpm.rawText, SUBSTITUTE(SUBSTITUTE(_xlpm.tag,"추가",""),"차감",""), _xlpm.fac, IFERROR(VALUE(_xlpm.rawText),""), _xlpm.base, G15, _xlpm.denom, $O$3, _xlpm.expected, IF(_xlpm.hasAdd, _xlpm.base/_xlpm.denom*_xlpm.fac, IF(_xlpm.hasSub, ROUNDDOWN(_xlpm.base/_xlpm.denom*_xlpm.fac,-1),"")), _xlpm.tgt0, IF(_xlpm.hasSub, Q15, IF(_xlpm.hasAdd, N15, "")), _xlpm.tgt, IF(_xlpm.tgt0="","",IFERROR(1*SUBSTITUTE(_xlpm.tgt0,",",""),"")), _xlpm.diff, IF(AND(_xlpm.expected<>"",_xlpm.tgt<>""), _xlpm.tgt-_xlpm.expected,""), _xlpm.ok, IF(_xlpm.diff<>"", ABS(_xlpm.diff)<=1, FALSE), IF(_xlpm.tag="", "NO TAG", IF(NOT(OR(_xlpm.hasAdd,_xlpm.hasSub)), "INVALID TAG", IF(_xlpm.fac="", "BAD NUM", IF(_xlpm.tgt="", "NO VAL", IF(_xlpm.ok,"OK","NG: "&TEXT(_xlpm.diff,"#,##0")) ) ) ) ) ) -> OK | AL15: 3353225.8 | AO15: 3300000 | AP15: 3353225.8 | AQ15: 3140330 | AR15: 3410000 | AS15: 3459677.4 | AT15: 3300000 | AU15: 3459677 | AV15: 3300000 | AW15: 3553226 | AX15: =SUM(AM15:AW15) -> 30276136
A16: =ROW()-5 -> 11 | B16: 유용복 | C16: =INDEX('정직원 (2)'!$B$4:$B$20,MATCH(임금대장!B16,'정직원 (2)'!$C$4:$C$20,0)) -> 0 | D16: =VLOOKUP(B16,'정직원 (2)'!$C$4:$F$20,4,0) -> 880621-1065632 | E16: =VLOOKUP(B16,'정직원 (2)'!$C$4:$J$81,8,0) -> 45649 | F16: =VLOOKUP(B16,'정직원 (2)'!$C$4:$L$81,10,0) -> 0 | G16: =VLOOKUP(B16,'정직원 (2)'!$C$4:$F$81,3,0) -> 3400000 | H16: =ROUNDDOWN(G16/291,0) -> 11683 | I16: =ROUNDUP(($G16/291*209),0) -> 2441925 | J16: =ROUNDDOWN(($G16/291*65.2),0) -> 761786 | K16: =ROUNDUP(($G16/291*8.8),0) -> 102818 | L16: =VLOOKUP(B16,'정직원 (2)'!$C$4:$O$95,13,0) -> 0 | M16: =ROUNDUP(($G16/291*8),0) -> 93471 | N16: =IF(OR(AI16="",AI16=0),0, IF(ISNUMBER(SEARCH("추가",AI16)), G16/$O$3*VALUE(SUBSTITUTE(SUBSTITUTE(TRIM(AI16)," ",""),"추가","")), 0)) -> 54838.71 | O16: =$O$3-P16 -> 31 | P16: =IF(ISNUMBER(SEARCH("차감",AI16)), VALUE(SUBSTITUTE(SUBSTITUTE(SUBSTITUTE(TRIM(AI16)," ",""),"차감",""),"일","")), IF(AND(YEAR(F16)=$M$3,MONTH(F16)=$N$3),$O$3-DAY(F16), IF(AND(YEAR(E16)=$M$3,MONTH(E16)=$N$3),DAY(E16)-1,0))) -> 0 | Q16: =ROUNDDOWN(G16/$O$3*P16,-1) -> 0 | S16: =ROUNDDOWN(H16*R16,-1) -> 0 | T16: =G16-Q16-S16+N16+L16 -> 3454838.7 | U16: 1800000 | V16: 1 | W16: =A16 -> 11 | X16: =B16 -> 유용복 | Y16: =IF(T16<800000,0,(VLOOKUP(T16,'세액표(1202)'!A:L,V16+1))) -> 117440 | Z16: =ROUNDDOWN(Y16*10%,-1) -> 11740 | AA16: 85500 | AB16: =ROUNDDOWN(T16*3.595%,-1) -> 124200 | AC16: =ROUNDDOWN(AB16*13.14%,-1) -> 16310 | AD16: =ROUNDDOWN(T16*0.9%,-1) -> 31090 | AE16: =L16 -> 0 | AG16: =SUM(Y16:AF16) -> 386280 | AH16: =T16-AG16 -> 3068558.7 | AI16: =VLOOKUP(D16,'정직원 (2)'!$F$4:$M$90,8,0) -> 0.5추가 | AJ16: =DATEDIF(DATE(IF(VALUE(LEFT(D16,2))>22,1900,2000)+VALUE(LEFT(D16,2)),VALUE(MID(D16,3,2)),VALUE(MID(D16,5,2))),TODAY(),"Y") -> 37 | AK16: =_xlfn.LET( _xlpm.tag0, AI16, _xlpm.tag, TRIM(SUBSTITUTE(SUBSTITUTE(_xlpm.tag0," ",""),CHAR(160),"")), _xlpm.hasAdd, ISNUMBER(SEARCH("추가",_xlpm.tag)), _xlpm.hasSub, ISNUMBER(SEARCH("차감",_xlpm.tag)), _xlpm.rawText, SUBSTITUTE(SUBSTITUTE(_xlpm.tag,"추가",""),"차감",""), _xlpm.fac, IFERROR(VALUE(_xlpm.rawText),""), _xlpm.base, G16, _xlpm.denom, $O$3, _xlpm.expected, IF(_xlpm.hasAdd, _xlpm.base/_xlpm.denom*_xlpm.fac, IF(_xlpm.hasSub, ROUNDDOWN(_xlpm.base/_xlpm.denom*_xlpm.fac,-1),"")), _xlpm.tgt0, IF(_xlpm.hasSub, Q16, IF(_xlpm.hasAdd, N16, "")), _xlpm.tgt, IF(_xlpm.tgt0="","",IFERROR(1*SUBSTITUTE(_xlpm.tgt0,",",""),"")), _xlpm.diff, IF(AND(_xlpm.expected<>"",_xlpm.tgt<>""), _xlpm.tgt-_xlpm.expected,""), _xlpm.ok, IF(_xlpm.diff<>"", ABS(_xlpm.diff)<=1, FALSE), IF(_xlpm.tag="", "NO TAG", IF(NOT(OR(_xlpm.hasAdd,_xlpm.hasSub)), "INVALID TAG", IF(_xlpm.fac="", "BAD NUM", IF(_xlpm.tgt="", "NO VAL", IF(_xlpm.ok,"OK","NG: "&TEXT(_xlpm.diff,"#,##0")) ) ) ) ) ) -> OK | AL16: 3454838.7 | AO16: 3513333.3 | AP16: 3564516.1 | AQ16: 3148390 | AR16: 3413333.3 | AS16: 3561290.3 | AT16: 3200000 | AU16: 3251613 | AV16: 3314285.7 | AW16: 3400000 | AX16: =SUM(AM16:AW16) -> 30366762
A17: =ROW()-5 -> 12 | B17: 안동화 | C17: =INDEX('정직원 (2)'!$B$4:$B$20,MATCH(임금대장!B17,'정직원 (2)'!$C$4:$C$20,0)) -> 롤 | D17: =VLOOKUP(B17,'정직원 (2)'!$C$4:$F$20,4,0) -> 700928-6101893 | E17: =VLOOKUP(B17,'정직원 (2)'!$C$4:$J$81,8,0) -> 45682 | F17: =VLOOKUP(B17,'정직원 (2)'!$C$4:$L$81,10,0) -> 0 | G17: =VLOOKUP(B17,'정직원 (2)'!$C$4:$F$81,3,0) -> 3400000 | H17: =ROUNDDOWN(G17/291,0) -> 11683 | I17: =ROUNDUP(($G17/291*209),0) -> 2441925 | J17: =ROUNDDOWN(($G17/291*65.2),0) -> 761786 | K17: =ROUNDUP(($G17/291*8.8),0) -> 102818 | L17: =VLOOKUP(B17,'정직원 (2)'!$C$4:$O$95,13,0) -> 0 | M17: =ROUNDUP(($G17/291*8),0) -> 93471 | N17: =IF(OR(AI17="",AI17=0),0, IF(ISNUMBER(SEARCH("추가",AI17)), G17/$O$3*VALUE(SUBSTITUTE(SUBSTITUTE(TRIM(AI17)," ",""),"추가","")), 0)) -> 54838.71 | O17: =$O$3-P17 -> 31 | P17: =IF(ISNUMBER(SEARCH("차감",AI17)), VALUE(SUBSTITUTE(SUBSTITUTE(SUBSTITUTE(TRIM(AI17)," ",""),"차감",""),"일","")), IF(AND(YEAR(F17)=$M$3,MONTH(F17)=$N$3),$O$3-DAY(F17), IF(AND(YEAR(E17)=$M$3,MONTH(E17)=$N$3),DAY(E17)-1,0))) -> 0 | Q17: =ROUNDDOWN(G17/$O$3*P17,-1) -> 0 | S17: =ROUNDDOWN(H17*R17,-1) -> 0 | T17: =G17-Q17-S17+N17+L17 -> 3454838.7 | U17: 1800000 | V17: 1 | W17: =A17 -> 12 | X17: =B17 -> 안동화 | Y17: =IF(T17<800000,0,(VLOOKUP(T17,'세액표(1202)'!A:L,V17+1))) -> 117440 | Z17: =ROUNDDOWN(Y17*10%,-1) -> 11740 | AA17: 85500 | AB17: =ROUNDDOWN(T17*3.595%,-1) -> 124200 | AC17: =ROUNDDOWN(AB17*13.14%,-1) -> 16310 | AD17: =ROUNDDOWN(T17*0.9%,-1) -> 31090 | AE17: =L17 -> 0 | AG17: =SUM(Y17:AF17) -> 386280 | AH17: =T17-AG17 -> 3068558.7 | AI17: =VLOOKUP(D17,'정직원 (2)'!$F$4:$M$25,8,0) -> 0.5추가 | AJ17: =DATEDIF(DATE(IF(VALUE(LEFT(D17,2))>22,1900,2000)+VALUE(LEFT(D17,2)),VALUE(MID(D17,3,2)),VALUE(MID(D17,5,2))),TODAY(),"Y") -> 55 | AK17: =_xlfn.LET( _xlpm.tag0, AI17, _xlpm.tag, TRIM(SUBSTITUTE(SUBSTITUTE(_xlpm.tag0," ",""),CHAR(160),"")), _xlpm.hasAdd, ISNUMBER(SEARCH("추가",_xlpm.tag)), _xlpm.hasSub, ISNUMBER(SEARCH("차감",_xlpm.tag)), _xlpm.rawText, SUBSTITUTE(SUBSTITUTE(_xlpm.tag,"추가",""),"차감",""), _xlpm.fac, IFERROR(VALUE(_xlpm.rawText),""), _xlpm.base, G17, _xlpm.denom, $O$3, _xlpm.expected, IF(_xlpm.hasAdd, _xlpm.base/_xlpm.denom*_xlpm.fac, IF(_xlpm.hasSub, ROUNDDOWN(_xlpm.base/_xlpm.denom*_xlpm.fac,-1),"")), _xlpm.tgt0, IF(_xlpm.hasSub, Q17, IF(_xlpm.hasAdd, N17, "")), _xlpm.tgt, IF(_xlpm.tgt0="","",IFERROR(1*SUBSTITUTE(_xlpm.tgt0,",",""),"")), _xlpm.diff, IF(AND(_xlpm.expected<>"",_xlpm.tgt<>""), _xlpm.tgt-_xlpm.expected,""), _xlpm.ok, IF(_xlpm.diff<>"", ABS(_xlpm.diff)<=1, FALSE), IF(_xlpm.tag="", "NO TAG", IF(NOT(OR(_xlpm.hasAdd,_xlpm.hasSub)), "INVALID TAG", IF(_xlpm.fac="", "BAD NUM", IF(_xlpm.tgt="", "NO VAL", IF(_xlpm.ok,"OK","NG: "&TEXT(_xlpm.diff,"#,##0")) ) ) ) ) ) -> OK | AL17: 3564516.1 | AO17: 3900000 | AP17: 3454838.7 | AQ17: 3440330 | AR17: 3610000 | AS17: 3353225.8 | AT17: 3300000 | AU17: 3566129 | AV17: 3300000 | AW17: 945170 | AX17: =SUM(AM17:AW17) -> 28869694
A18: =ROW()-5 -> 13 | B18: 최장현 | C18: =INDEX('정직원 (2)'!$B$4:$B$20,MATCH(임금대장!B18,'정직원 (2)'!$C$4:$C$20,0)) -> 초다이 | D18: =VLOOKUP(B18,'정직원 (2)'!$C$4:$F$20,4,0) -> 930114-1064818 | E18: =VLOOKUP(B18,'정직원 (2)'!$C$4:$J$81,8,0) -> 45693 | F18: =VLOOKUP(B18,'정직원 (2)'!$C$4:$L$81,10,0) -> 0 | G18: =VLOOKUP(B18,'정직원 (2)'!$C$4:$F$81,3,0) -> 3800000 | H18: =ROUNDDOWN(G18/291,0) -> 13058 | I18: =ROUNDUP(($G18/291*209),0) -> 2729210 | J18: =ROUNDDOWN(($G18/291*65.2),0) -> 851408 | K18: =ROUNDUP(($G18/291*8.8),0) -> 114915 | L18: =VLOOKUP(B18,'정직원 (2)'!$C$4:$O$95,13,0) -> 0 | M18: =ROUNDUP(($G18/291*8),0) -> 104468 | N18: =IF(OR(AI18="",AI18=0),0, IF(ISNUMBER(SEARCH("추가",AI18)), G18/$O$3*VALUE(SUBSTITUTE(SUBSTITUTE(TRIM(AI18)," ",""),"추가","")), 0)) -> 183870.97 | O18: =$O$3-P18 -> 31 | P18: =IF(ISNUMBER(SEARCH("차감",AI18)), VALUE(SUBSTITUTE(SUBSTITUTE(SUBSTITUTE(TRIM(AI18)," ",""),"차감",""),"일","")), IF(AND(YEAR(F18)=$M$3,MONTH(F18)=$N$3),$O$3-DAY(F18), IF(AND(YEAR(E18)=$M$3,MONTH(E18)=$N$3),DAY(E18)-1,0))) -> 0 | Q18: =ROUNDDOWN(G18/$O$3*P18,-1) -> 0 | S18: =ROUNDDOWN(H18*R18,-1) -> 0 | T18: =G18-Q18-S18+N18+L18 -> 3983871 | U18: 1800000 | V18: 1 | W18: =A18 -> 13 | X18: =B18 -> 최장현 | Y18: =IF(T18<800000,0,(VLOOKUP(T18,'세액표(1202)'!A:L,V18+1))) -> 190620 | Z18: =ROUNDDOWN(Y18*10%,-1) -> 19060 | AA18: 85500 | AB18: =ROUNDDOWN(T18*3.595%,-1) -> 143220 | AC18: =ROUNDDOWN(AB18*13.14%,-1) -> 18810 | AD18: =ROUNDDOWN(T18*0.9%,-1) -> 35850 | AE18: =L18 -> 0 | AG18: =SUM(Y18:AF18) -> 493060 | AH18: =T18-AG18 -> 3490811 | AI18: =VLOOKUP(D18,'정직원 (2)'!$F$4:$M$25,8,0) -> 1.5추가 | AJ18: =DATEDIF(DATE(IF(VALUE(LEFT(D18,2))>22,1900,2000)+VALUE(LEFT(D18,2)),VALUE(MID(D18,3,2)),VALUE(MID(D18,5,2))),TODAY(),"Y") -> 33 | AK18: =_xlfn.LET( _xlpm.tag0, AI18, _xlpm.tag, TRIM(SUBSTITUTE(SUBSTITUTE(_xlpm.tag0," ",""),CHAR(160),"")), _xlpm.hasAdd, ISNUMBER(SEARCH("추가",_xlpm.tag)), _xlpm.hasSub, ISNUMBER(SEARCH("차감",_xlpm.tag)), _xlpm.rawText, SUBSTITUTE(SUBSTITUTE(_xlpm.tag,"추가",""),"차감",""), _xlpm.fac, IFERROR(VALUE(_xlpm.rawText),""), _xlpm.base, G18, _xlpm.denom, $O$3, _xlpm.expected, IF(_xlpm.hasAdd, _xlpm.base/_xlpm.denom*_xlpm.fac, IF(_xlpm.hasSub, ROUNDDOWN(_xlpm.base/_xlpm.denom*_xlpm.fac,-1),"")), _xlpm.tgt0, IF(_xlpm.hasSub, Q18, IF(_xlpm.hasAdd, N18, "")), _xlpm.tgt, IF(_xlpm.tgt0="","",IFERROR(1*SUBSTITUTE(_xlpm.tgt0,",",""),"")), _xlpm.diff, IF(AND(_xlpm.expected<>"",_xlpm.tgt<>""), _xlpm.tgt-_xlpm.expected,""), _xlpm.ok, IF(_xlpm.diff<>"", ABS(_xlpm.diff)<=1, FALSE), IF(_xlpm.tag="", "NO TAG", IF(NOT(OR(_xlpm.hasAdd,_xlpm.hasSub)), "INVALID TAG", IF(_xlpm.fac="", "BAD NUM", IF(_xlpm.tgt="", "NO VAL", IF(_xlpm.ok,"OK","NG: "&TEXT(_xlpm.diff,"#,##0")) ) ) ) ) ) -> OK | AL18: 3454838.7 | AO18: 3513333.3 | AP18: 3674193.5 | AQ18: 3235490 | AR18: 3626666.7 | AS18: 3893548.4 | AT18: 3400000 | AU18: 3454839 | AV18: 2914290 | AW18: #N/A
A19: =ROW()-5 -> 14 | B19: 이준수 | C19: =INDEX('정직원 (2)'!$B$4:$B$20,MATCH(임금대장!B19,'정직원 (2)'!$C$4:$C$20,0)) -> 홀 | D19: =VLOOKUP(B19,'정직원 (2)'!$C$4:$F$20,4,0) -> 991231-1152511 | E19: =VLOOKUP(B19,'정직원 (2)'!$C$4:$J$81,8,0) -> 45709 | F19: =VLOOKUP(B19,'정직원 (2)'!$C$4:$L$81,10,0) -> 0 | G19: =VLOOKUP(B19,'정직원 (2)'!$C$4:$F$81,3,0) -> 3500000 | H19: =ROUNDDOWN(G19/291,0) -> 12027 | I19: =ROUNDDOWN(($G19/291*209),0) -> 2513745 | J19: =ROUNDDOWN(($G19/291*65.2),0) -> 784192 | K19: =ROUNDUP(($G19/291*8.8),0) -> 105842 | L19: =VLOOKUP(B19,'정직원 (2)'!$C$4:$O$95,13,0) -> 0 | M19: =ROUNDUP(($G19/291*8),0) -> 96220 | N19: =IF(OR(AI19="",AI19=0),0, IF(ISNUMBER(SEARCH("추가",AI19)), G19/$O$3*VALUE(SUBSTITUTE(SUBSTITUTE(TRIM(AI19)," ",""),"추가","")), 0)) -> 169354.84 | O19: =$O$3-P19 -> 31 | P19: =IF(ISNUMBER(SEARCH("차감",AI19)), VALUE(SUBSTITUTE(SUBSTITUTE(SUBSTITUTE(TRIM(AI19)," ",""),"차감",""),"일","")), IF(AND(YEAR(F19)=$M$3,MONTH(F19)=$N$3),$O$3-DAY(F19), IF(AND(YEAR(E19)=$M$3,MONTH(E19)=$N$3),DAY(E19)-1,0))) -> 0 | Q19: =ROUNDDOWN(G19/$O$3*P19,-1) -> 0 | S19: =ROUNDDOWN(H19*R19,-1) -> 0 | T19: =G19-Q19-S19+N19+L19 -> 3669354.8 | U19: 1800000 | V19: 1 | W19: =A19 -> 14 | X19: =B19 -> 이준수 | Y19: =IF(T19<800000,0,(VLOOKUP(T19,'세액표(1202)'!A:L,V19+1))) -> 144330 | Z19: =ROUNDDOWN(Y19*10%,-1) -> 14430 | AA19: 85500 | AB19: =ROUNDDOWN(T19*3.595%,-1) -> 131910 | AC19: =ROUNDDOWN(AB19*13.14%,-1) -> 17330 | AD19: =ROUNDDOWN(T19*0.9%,-1) -> 33020 | AE19: =L19 -> 0 | AG19: =SUM(Y19:AF19) -> 426520 | AH19: =T19-AG19 -> 3242834.8 | AI19: =VLOOKUP(D19,'정직원 (2)'!$F$4:$M$25,8,0) -> 1.5추가 | AJ19: =DATEDIF(DATE(IF(VALUE(LEFT(D19,2))>22,1900,2000)+VALUE(LEFT(D19,2)),VALUE(MID(D19,3,2)),VALUE(MID(D19,5,2))),TODAY(),"Y") -> 26 | AK19: =_xlfn.LET( _xlpm.tag0, AI19, _xlpm.tag, TRIM(SUBSTITUTE(SUBSTITUTE(_xlpm.tag0," ",""),CHAR(160),"")), _xlpm.hasAdd, ISNUMBER(SEARCH("추가",_xlpm.tag)), _xlpm.hasSub, ISNUMBER(SEARCH("차감",_xlpm.tag)), _xlpm.rawText, SUBSTITUTE(SUBSTITUTE(_xlpm.tag,"추가",""),"차감",""), _xlpm.fac, IFERROR(VALUE(_xlpm.rawText),""), _xlpm.base, G19, _xlpm.denom, $O$3, _xlpm.expected, IF(_xlpm.hasAdd, _xlpm.base/_xlpm.denom*_xlpm.fac, IF(_xlpm.hasSub, ROUNDDOWN(_xlpm.base/_xlpm.denom*_xlpm.fac,-1),"")), _xlpm.tgt0, IF(_xlpm.hasSub, Q19, IF(_xlpm.hasAdd, N19, "")), _xlpm.tgt, IF(_xlpm.tgt0="","",IFERROR(1*SUBSTITUTE(_xlpm.tgt0,",",""),"")), _xlpm.diff, IF(AND(_xlpm.expected<>"",_xlpm.tgt<>""), _xlpm.tgt-_xlpm.expected,""), _xlpm.ok, IF(_xlpm.diff<>"", ABS(_xlpm.diff)<=1, FALSE), IF(_xlpm.tag="", "NO TAG", IF(NOT(OR(_xlpm.hasAdd,_xlpm.hasSub)), "INVALID TAG", IF(_xlpm.fac="", "BAD NUM", IF(_xlpm.tgt="", "NO VAL", IF(_xlpm.ok,"OK","NG: "&TEXT(_xlpm.diff,"#,##0")) ) ) ) ) ) -> OK | AL19: 3743550 | AO19: 2830000 | AP19: 3619354.8 | AQ19: 2714520 | AR19: 3520000 | AS19: 3619354.8 | AT19: 3300000 | AU19: 3353226 | AV19: 942860 | AW19: #N/A
A20: =ROW()-5 -> 15 | B20: 이부순 | C20: =INDEX('정직원 (2)'!$B$4:$B$20,MATCH(임금대장!B20,'정직원 (2)'!$C$4:$C$20,0)) -> 롤 | D20: =VLOOKUP(B20,'정직원 (2)'!$C$4:$F$20,4,0) -> 690917-2451117 | E20: =VLOOKUP(B20,'정직원 (2)'!$C$4:$J$81,8,0) -> 45720 | F20: =VLOOKUP(B20,'정직원 (2)'!$C$4:$L$81,10,0) -> 0 | G20: =VLOOKUP(B20,'정직원 (2)'!$C$4:$F$81,3,0) -> 3300000 | H20: =ROUNDDOWN(G20/291,0) -> 11340 | I20: =ROUNDDOWN(($G20/291*209),0) -> 2370103 | J20: =ROUNDDOWN(($G20/291*65.2),0) -> 739381 | K20: =ROUNDUP(($G20/291*8.8),0) -> 99794 | L20: =VLOOKUP(B20,'정직원 (2)'!$C$4:$O$95,13,0) -> 0 | M20: =ROUNDUP(($G20/291*8),0) -> 90722 | N20: =IF(OR(AI20="",AI20=0),0, IF(ISNUMBER(SEARCH("추가",AI20)), G20/$O$3*VALUE(SUBSTITUTE(SUBSTITUTE(TRIM(AI20)," ",""),"추가","")), 0)) -> 53225.806 | O20: =$O$3-P20 -> 31 | P20: =IF(ISNUMBER(SEARCH("차감",AI20)), VALUE(SUBSTITUTE(SUBSTITUTE(SUBSTITUTE(TRIM(AI20)," ",""),"차감",""),"일","")), IF(AND(YEAR(F20)=$M$3,MONTH(F20)=$N$3),$O$3-DAY(F20), IF(AND(YEAR(E20)=$M$3,MONTH(E20)=$N$3),DAY(E20)-1,0))) -> 0 | Q20: =ROUNDDOWN(G20/$O$3*P20,-1) -> 0 | S20: =ROUNDDOWN(H20*R20,-1) -> 0 | T20: =G20-Q20-S20+N20+L20 -> 3353225.8 | U20: 1800000 | V20: 1 | W20: =A20 -> 15 | X20: =B20 -> 이부순 | Y20: =IF(T20<800000,0,(VLOOKUP(T20,'세액표(1202)'!A:L,V20+1))) -> 105210 | Z20: =ROUNDDOWN(Y20*10%,-1) -> 10520 | AA20: 85500 | AB20: =ROUNDDOWN(T20*3.595%,-1) -> 120540 | AC20: =ROUNDDOWN(AB20*13.14%,-1) -> 15830 | AD20: =ROUNDDOWN(T20*0.9%,-1) -> 30170 | AE20: =L20 -> 0 | AG20: =SUM(Y20:AF20) -> 367770 | AH20: =T20-AG20 -> 2985455.8 | AI20: =VLOOKUP(D20,'정직원 (2)'!$F$4:$M$25,8,0) -> 0.5추가 | AJ20: =DATEDIF(DATE(IF(VALUE(LEFT(D20,2))>22,1900,2000)+VALUE(LEFT(D20,2)),VALUE(MID(D20,3,2)),VALUE(MID(D20,5,2))),TODAY(),"Y") -> 56 | AK20: =_xlfn.LET( _xlpm.tag0, AI20, _xlpm.tag, TRIM(SUBSTITUTE(SUBSTITUTE(_xlpm.tag0," ",""),CHAR(160),"")), _xlpm.hasAdd, ISNUMBER(SEARCH("추가",_xlpm.tag)), _xlpm.hasSub, ISNUMBER(SEARCH("차감",_xlpm.tag)), _xlpm.rawText, SUBSTITUTE(SUBSTITUTE(_xlpm.tag,"추가",""),"차감",""), _xlpm.fac, IFERROR(VALUE(_xlpm.rawText),""), _xlpm.base, G20, _xlpm.denom, $O$3, _xlpm.expected, IF(_xlpm.hasAdd, _xlpm.base/_xlpm.denom*_xlpm.fac, IF(_xlpm.hasSub, ROUNDDOWN(_xlpm.base/_xlpm.denom*_xlpm.fac,-1),"")), _xlpm.tgt0, IF(_xlpm.hasSub, Q20, IF(_xlpm.hasAdd, N20, "")), _xlpm.tgt, IF(_xlpm.tgt0="","",IFERROR(1*SUBSTITUTE(_xlpm.tgt0,",",""),"")), _xlpm.diff, IF(AND(_xlpm.expected<>"",_xlpm.tgt<>""), _xlpm.tgt-_xlpm.expected,""), _xlpm.ok, IF(_xlpm.diff<>"", ABS(_xlpm.diff)<=1, FALSE), IF(_xlpm.tag="", "NO TAG", IF(NOT(OR(_xlpm.hasAdd,_xlpm.hasSub)), "INVALID TAG", IF(_xlpm.fac="", "BAD NUM", IF(_xlpm.tgt="", "NO VAL", IF(_xlpm.ok,"OK","NG: "&TEXT(_xlpm.diff,"#,##0")) ) ) ) ) ) -> OK | AL20: 3353225.8 | AO20: 3300000 | AP20: 3353225.8 | AQ20: 3140330 | AR20: 3410000 | AS20: 3512903.2 | AT20: 3300000 | AU20: 2980650 | AV20: #N/A | AW20: #N/A
A21: =ROW()-5 -> 16 | B21: 김예찬 | C21: =INDEX('정직원 (2)'!$B$4:$B$20,MATCH(임금대장!B21,'정직원 (2)'!$C$4:$C$20,0)) -> 핫/즉석 | D21: =VLOOKUP(B21,'정직원 (2)'!$C$4:$F$20,4,0) -> 980825-1156317 | E21: =VLOOKUP(B21,'정직원 (2)'!$C$4:$J$81,8,0) -> 45771 | F21: =VLOOKUP(B21,'정직원 (2)'!$C$4:$L$81,10,0) -> 0 | G21: =VLOOKUP(B21,'정직원 (2)'!$C$4:$F$81,3,0) -> 3400000 | H21: =ROUNDDOWN(G21/291,0) -> 11683 | I21: =ROUNDUP(($G21/291*209),0) -> 2441925 | J21: =ROUNDDOWN(($G21/291*65.2),0) -> 761786 | K21: =ROUNDUP(($G21/291*8.8),0) -> 102818 | L21: =VLOOKUP(B21,'정직원 (2)'!$C$4:$O$95,13,0) -> 0 | M21: =ROUNDUP(($G21/291*8),0) -> 93471 | N21: =IF(OR(AI21="",AI21=0),0, IF(ISNUMBER(SEARCH("추가",AI21)), G21/$O$3*VALUE(SUBSTITUTE(SUBSTITUTE(TRIM(AI21)," ",""),"추가","")), 0)) -> 164516.13 | O21: =$O$3-P21 -> 31 | P21: =IF(ISNUMBER(SEARCH("차감",AI21)), VALUE(SUBSTITUTE(SUBSTITUTE(SUBSTITUTE(TRIM(AI21)," ",""),"차감",""),"일","")), IF(AND(YEAR(F21)=$M$3,MONTH(F21)=$N$3),$O$3-DAY(F21), IF(AND(YEAR(E21)=$M$3,MONTH(E21)=$N$3),DAY(E21)-1,0))) -> 0 | Q21: =ROUNDDOWN(G21/$O$3*P21,-1) -> 0 | S21: =ROUNDDOWN(H21*R21,-1) -> 0 | T21: =G21-Q21-S21+N21+L21 -> 3564516.1 | U21: 1800000 | V21: 1 | W21: =A21 -> 16 | X21: =B21 -> 김예찬 | Y21: =IF(T21<800000,0,(VLOOKUP(T21,'세액표(1202)'!A:L,V21+1))) -> 132110 | Z21: =ROUNDDOWN(Y21*10%,-1) -> 13210 | AA21: 85500 | AB21: =ROUNDDOWN(T21*3.595%,-1) -> 128140 | AC21: =ROUNDDOWN(AB21*13.14%,-1) -> 16830 | AD21: =ROUNDDOWN(T21*0.9%,-1) -> 32080 | AE21: =L21 -> 0 | AG21: =SUM(Y21:AF21) -> 407870 | AH21: =T21-AG21 -> 3156646.1 | AI21: =VLOOKUP(D21,'정직원 (2)'!$F$4:$M$25,8,0) -> 1.5추가 | AJ21: =DATEDIF(DATE(IF(VALUE(LEFT(D21,2))>22,1900,2000)+VALUE(LEFT(D21,2)),VALUE(MID(D21,3,2)),VALUE(MID(D21,5,2))),TODAY(),"Y") -> 27 | AK21: =_xlfn.LET( _xlpm.tag0, AI21, _xlpm.tag, TRIM(SUBSTITUTE(SUBSTITUTE(_xlpm.tag0," ",""),CHAR(160),"")), _xlpm.hasAdd, ISNUMBER(SEARCH("추가",_xlpm.tag)), _xlpm.hasSub, ISNUMBER(SEARCH("차감",_xlpm.tag)), _xlpm.rawText, SUBSTITUTE(SUBSTITUTE(_xlpm.tag,"추가",""),"차감",""), _xlpm.fac, IFERROR(VALUE(_xlpm.rawText),""), _xlpm.base, G21, _xlpm.denom, $O$3, _xlpm.expected, IF(_xlpm.hasAdd, _xlpm.base/_xlpm.denom*_xlpm.fac, IF(_xlpm.hasSub, ROUNDDOWN(_xlpm.base/_xlpm.denom*_xlpm.fac,-1),"")), _xlpm.tgt0, IF(_xlpm.hasSub, Q21, IF(_xlpm.hasAdd, N21, "")), _xlpm.tgt, IF(_xlpm.tgt0="","",IFERROR(1*SUBSTITUTE(_xlpm.tgt0,",",""),"")), _xlpm.diff, IF(AND(_xlpm.expected<>"",_xlpm.tgt<>""), _xlpm.tgt-_xlpm.expected,""), _xlpm.ok, IF(_xlpm.diff<>"", ABS(_xlpm.diff)<=1, FALSE), IF(_xlpm.tag="", "NO TAG", IF(NOT(OR(_xlpm.hasAdd,_xlpm.hasSub)), "INVALID TAG", IF(_xlpm.fac="", "BAD NUM", IF(_xlpm.tgt="", "NO VAL", IF(_xlpm.ok,"OK","NG: "&TEXT(_xlpm.diff,"#,##0")) ) ) ) ) ) -> OK | AL21: 3564516.1 | AO21: 3513333.3 | AP21: 3400000 | AQ21: 3345170 | AR21: 3513333.3 | AS21: 3783871 | AT21: 793340 | AU21: 2270970 | AV21: #N/A | AW21: #N/A
A22: =ROW()-5 -> 17 | B22: 조윤희 | C22: =INDEX('정직원 (2)'!$B$4:$B$77,MATCH(임금대장!B22,'정직원 (2)'!$C$4:$C$77,0)) -> 0 | D22: =VLOOKUP(B22,'정직원 (2)'!$C$4:$F$77,4,0) -> 890428-2150912 | E22: =VLOOKUP(B22,'정직원 (2)'!$C$4:$J$81,8,0) -> 45809 | F22: =VLOOKUP(B22,'정직원 (2)'!$C$4:$L$81,10,0) -> 0 | G22: 3371380 | H22: =ROUNDDOWN(G22/291,0) -> 11585 | I22: =ROUNDDOWN(($G22/291*209),0) -> 2421369 | J22: =ROUNDDOWN(($G22/291*65.2),0) -> 755374 | K22: =ROUNDUP(($G22/291*8.8),0) -> 101953 | L22: =VLOOKUP(B22,'정직원 (2)'!$C$4:$O$95,13,0) -> 0 | M22: =ROUNDUP(($G22/291*8),0) -> 92684 | N22: =IF(OR(AI22="",AI22=0),0, IF(ISNUMBER(SEARCH("추가",AI22)), G22/$O$3*VALUE(SUBSTITUTE(SUBSTITUTE(TRIM(AI22)," ",""),"추가","")), 0)) -> 0 | O22: =$O$3-P22 -> 31 | P22: =IF(ISNUMBER(SEARCH("차감",AI22)), VALUE(SUBSTITUTE(SUBSTITUTE(SUBSTITUTE(TRIM(AI22)," ",""),"차감",""),"일","")), IF(AND(YEAR(F22)=$M$3,MONTH(F22)=$N$3),$O$3-DAY(F22), IF(AND(YEAR(E22)=$M$3,MONTH(E22)=$N$3),DAY(E22)-1,0))) -> 0 | Q22: =ROUNDDOWN(G22/$O$3*P22,-1) -> 0 | S22: =ROUNDDOWN(H22*R22,-1) -> 0 | T22: =G22-Q22-S22+N22+L22 -> 3371380 | U22: 1800000 | V22: 1 | W22: =A22 -> 17 | X22: =B22 -> 조윤희 | Y22: =IF(T22<800000,0,(VLOOKUP(T22,'세액표(1202)'!A:L,V22+1))) -> 107660 | Z22: =ROUNDDOWN(Y22*10%,-1) -> 10760 | AA22: 85500 | AB22: =ROUNDDOWN(T22*3.595%,-1) -> 121200 | AC22: =ROUNDDOWN(AB22*13.14%,-1) -> 15920 | AD22: =ROUNDDOWN(T22*0.9%,-1) -> 30340 | AE22: =L22 -> 0 | AG22: =SUM(Y22:AF22) -> 371380 | AH22: =T22-AG22 -> 3000000 | AI22: =VLOOKUP(D22,'정직원 (2)'!$F$4:$M$90,8,0) -> 0 | AJ22: =DATEDIF(DATE(IF(VALUE(LEFT(D22,2))>22,1900,2000)+VALUE(LEFT(D22,2)),VALUE(MID(D22,3,2)),VALUE(MID(D22,5,2))),TODAY(),"Y") -> 36 | AK22: =_xlfn.LET( _xlpm.tag0, AI22, _xlpm.tag, TRIM(SUBSTITUTE(SUBSTITUTE(_xlpm.tag0," ",""),CHAR(160),"")), _xlpm.hasAdd, ISNUMBER(SEARCH("추가",_xlpm.tag)), _xlpm.hasSub, ISNUMBER(SEARCH("차감",_xlpm.tag)), _xlpm.rawText, SUBSTITUTE(SUBSTITUTE(_xlpm.tag,"추가",""),"차감",""), _xlpm.fac, IFERROR(VALUE(_xlpm.rawText),""), _xlpm.base, G22, _xlpm.denom, $O$3, _xlpm.expected, IF(_xlpm.hasAdd, _xlpm.base/_xlpm.denom*_xlpm.fac, IF(_xlpm.hasSub, ROUNDDOWN(_xlpm.base/_xlpm.denom*_xlpm.fac,-1),"")), _xlpm.tgt0, IF(_xlpm.hasSub, Q22, IF(_xlpm.hasAdd, N22, "")), _xlpm.tgt, IF(_xlpm.tgt0="","",IFERROR(1*SUBSTITUTE(_xlpm.tgt0,",",""),"")), _xlpm.diff, IF(AND(_xlpm.expected<>"",_xlpm.tgt<>""), _xlpm.tgt-_xlpm.expected,""), _xlpm.ok, IF(_xlpm.diff<>"", ABS(_xlpm.diff)<=1, FALSE), IF(_xlpm.tag="", "NO TAG", IF(NOT(OR(_xlpm.hasAdd,_xlpm.hasSub)), "INVALID TAG", IF(_xlpm.fac="", "BAD NUM", IF(_xlpm.tgt="", "NO VAL", IF(_xlpm.ok,"OK","NG: "&TEXT(_xlpm.diff,"#,##0")) ) ) ) ) ) -> INVALID TAG | AL22: 3364390 | AO22: 3364390 | AP22: 3364390 | AQ22: 3364390 | AR22: 3364390 | AS22: 3566129 | AT22: 3300000 | AU22: 2341940 | AV22: #N/A | AW22: #N/A
A23: =ROW()-5 -> 18 | B23: 나지훈 | C23: =INDEX('정직원 (2)'!$B$4:$B$77,MATCH(임금대장!B23,'정직원 (2)'!$C$4:$C$77,0)) -> 핫/즉석 | D23: =VLOOKUP(B23,'정직원 (2)'!$C$4:$F$77,4,0) -> 960115-1020619 | E23: 45841 | F23: =VLOOKUP(B23,'정직원 (2)'!$C$4:$L$81,10,0) -> 0 | G23: =VLOOKUP(B23,'정직원 (2)'!$C$4:$F$81,3,0) -> 3300000 | H23: =ROUNDDOWN(G23/291,0) -> 11340 | I23: =ROUNDDOWN(($G23/291*209),0) -> 2370103 | J23: =ROUNDDOWN(($G23/291*65.2),0) -> 739381 | K23: =ROUNDUP(($G23/291*8.8),0) -> 99794 | L23: =VLOOKUP(B23,'정직원 (2)'!$C$4:$O$95,13,0) -> 0 | M23: =ROUNDUP(($G23/291*8),0) -> 90722 | N23: =IF(OR(AI23="",AI23=0),0, IF(ISNUMBER(SEARCH("추가",AI23)), G23/$O$3*VALUE(SUBSTITUTE(SUBSTITUTE(TRIM(AI23)," ",""),"추가","")), 0)) -> 372580.65 | O23: =$O$3-P23 -> 31 | P23: =IF(ISNUMBER(SEARCH("차감",AI23)), VALUE(SUBSTITUTE(SUBSTITUTE(SUBSTITUTE(TRIM(AI23)," ",""),"차감",""),"일","")), IF(AND(YEAR(F23)=$M$3,MONTH(F23)=$N$3),$O$3-DAY(F23), IF(AND(YEAR(E23)=$M$3,MONTH(E23)=$N$3),DAY(E23)-1,0))) -> 0 | Q23: =ROUNDDOWN(G23/$O$3*P23,-1) -> 0 | S23: =ROUNDDOWN(H23*R23,-1) -> 0 | T23: =G23-Q23-S23+N23+L23 -> 3672580.6 | U23: 1800000 | V23: 1 | W23: =A23 -> 18 | X23: =B23 -> 나지훈 | Y23: =IF(T23<800000,0,(VLOOKUP(T23,'세액표(1202)'!A:L,V23+1))) -> 144330 | Z23: =ROUNDDOWN(Y23*10%,-1) -> 14430 | AA23: 85500 | AB23: =ROUNDDOWN(T23*3.595%,-1) -> 132020 | AC23: =ROUNDDOWN(AB23*13.14%,-1) -> 17340 | AD23: =ROUNDDOWN(T23*0.9%,-1) -> 33050 | AE23: =L23 -> 0 | AG23: =SUM(Y23:AF23) -> 426670 | AH23: =T23-AG23 -> 3245910.6 | AI23: =VLOOKUP(D23,'정직원 (2)'!$F$4:$M$25,8,0) -> 3.5추가 | AJ23: =DATEDIF(DATE(IF(VALUE(LEFT(D23,2))>22,1900,2000)+VALUE(LEFT(D23,2)),VALUE(MID(D23,3,2)),VALUE(MID(D23,5,2))),TODAY(),"Y") -> 30 | AK23: =_xlfn.LET( _xlpm.tag0, AI23, _xlpm.tag, TRIM(SUBSTITUTE(SUBSTITUTE(_xlpm.tag0," ",""),CHAR(160),"")), _xlpm.hasAdd, ISNUMBER(SEARCH("추가",_xlpm.tag)), _xlpm.hasSub, ISNUMBER(SEARCH("차감",_xlpm.tag)), _xlpm.rawText, SUBSTITUTE(SUBSTITUTE(_xlpm.tag,"추가",""),"차감",""), _xlpm.fac, IFERROR(VALUE(_xlpm.rawText),""), _xlpm.base, G23, _xlpm.denom, $O$3, _xlpm.expected, IF(_xlpm.hasAdd, _xlpm.base/_xlpm.denom*_xlpm.fac, IF(_xlpm.hasSub, ROUNDDOWN(_xlpm.base/_xlpm.denom*_xlpm.fac,-1),"")), _xlpm.tgt0, IF(_xlpm.hasSub, Q23, IF(_xlpm.hasAdd, N23, "")), _xlpm.tgt, IF(_xlpm.tgt0="","",IFERROR(1*SUBSTITUTE(_xlpm.tgt0,",",""),"")), _xlpm.diff, IF(AND(_xlpm.expected<>"",_xlpm.tgt<>""), _xlpm.tgt-_xlpm.expected,""), _xlpm.ok, IF(_xlpm.diff<>"", ABS(_xlpm.diff)<=1, FALSE), IF(_xlpm.tag="", "NO TAG", IF(NOT(OR(_xlpm.hasAdd,_xlpm.hasSub)), "INVALID TAG", IF(_xlpm.fac="", "BAD NUM", IF(_xlpm.tgt="", "NO VAL", IF(_xlpm.ok,"OK","NG: "&TEXT(_xlpm.diff,"#,##0")) ) ) ) ) ) -> OK | AL23: 3353225.8 | AO23: 3410000 | AP23: 3300000 | AQ23: 798390 | AR23: 3364390 | AS23: 3566129 | AT23: 3300000 | AU23: 2341940 | AV23: #N/A | AW23: #N/A
